Workbook
Name 귀케어목록: 설정_코스수당!$M$5:$M$8
Name 날짜목록: 설정_코스수당!$J$5:$J$35
Name 마사지사목록: 설정_코스수당!$N$5:$N$54
Name 방번호목록: 설정_코스수당!$L$5:$L$34
Name 시간목록: 설정_코스수당!$K$5:$K$35
Name 코스목록: 설정_코스수당!$A$6:$A$10

Sheet 오늘대시보드
A1: 오늘근무현황 — 실시간 대시보드
A3: 조회날짜 | B3: 46176
A5: 오늘 상태 요약 | D5: 방문완료 코스별 | G5: 월간 상태 요약
A6: 오늘 예약건수 | B6: =COUNTIFS(실시간콜입력!$B:$B,$B$3,실시간콜입력!$O:$O,"<>") -> 0 | D6: A코스 | E6: =COUNTIFS(실시간콜입력!$B:$B,$B$3,실시간콜입력!$E:$E,"A",실시간콜입력!$O:$O,"방문완료") -> 0 | G6: 월 방문완료 콜 | H6: =COUNTIFS(실시간콜입력!$O:$O,"방문완료") -> 0
A7: 오늘 방문완료 콜 | B7: =COUNTIFS(실시간콜입력!$B:$B,$B$3,실시간콜입력!$O:$O,"방문완료") -> 0 | D7: B코스 | E7: =COUNTIFS(실시간콜입력!$B:$B,$B$3,실시간콜입력!$E:$E,"B",실시간콜입력!$O:$O,"방문완료") -> 0 | G7: 월 예약건수 | H7: =COUNTIFS(실시간콜입력!$B:$B,">="&DATE(YEAR($B$3),MONTH($B$3),1),실시간콜입력!$B:$B,"<"&EDATE(DATE(YEAR($B$3),MONTH($B$3),1),1),실시간콜입력!$O:$O,"<>") -> 0
A8: 오늘 노쇼 | B8: =COUNTIFS(실시간콜입력!$B:$B,$B$3,실시간콜입력!$O:$O,"노쇼") -> 0 | D8: C코스 | E8: =COUNTIFS(실시간콜입력!$B:$B,$B$3,실시간콜입력!$E:$E,"C",실시간콜입력!$O:$O,"방문완료") -> 0 | G8: 월 노쇼 | H8: =COUNTIFS(실시간콜입력!$O:$O,"노쇼") -> 0
A9: 오늘 취소 | B9: =COUNTIFS(실시간콜입력!$B:$B,$B$3,실시간콜입력!$O:$O,"취소") -> 0 | D9: D코스 | E9: =COUNTIFS(실시간콜입력!$B:$B,$B$3,실시간콜입력!$E:$E,"D",실시간콜입력!$O:$O,"방문완료") -> 0 | G9: 월 취소 | H9: =COUNTIFS(실시간콜입력!$O:$O,"취소") -> 0
A10: 오늘 결제합계 | B10: =SUMIFS(실시간콜입력!$J:$J,실시간콜입력!$B:$B,$B$3,실시간콜입력!$O:$O,"방문완료") -> 0 | D10: E코스 | E10: =COUNTIFS(실시간콜입력!$B:$B,$B$3,실시간콜입력!$E:$E,"E",실시간콜입력!$O:$O,"방문완료") -> 0 | G10: 월 방문완료 매출 | H10: =SUMIFS(실시간콜입력!$J:$J,실시간콜입력!$O:$O,"방문완료") -> 0
A11: 오늘 마사지사 담당콜 | B11: =SUMIFS(마사지사일정산!$K:$K,마사지사일정산!$A:$A,$B$3) -> 0
A12: 오늘 마사지사 정산 | B12: =SUMIFS(마사지사일정산!$L:$L,마사지사일정산!$A:$A,$B$3) -> 0
A14: 오늘 코스별 실시간 입력은 [실시간콜입력] 시트에 손님 1명/1건씩 입력
A15: 1) 손님 올 때마다 실시간콜입력에 날짜, 시간, 방번호, 코스, 마사지사1/2만 입력
A16: 2) 코스별 결제금액과 마사지사 수당은 설정_코스수당 기준으로 자동 기입
A17: 3) B코스 귀케어 수당은 귀케어일정산에서 당일 정상근무자끼리 자동 N분의1
A18: 4) 운영팀 일일인센은 총콜 30/40/50콜 기준으로 자동 계산
A19: 5) 월마감에서 만근 20일, 갯수왕 TOP3, 40콜 이상 조건 자동 반영
G24: g

Sheet 실시간콜입력
A1: 실시간콜입력
A2: 하루 100개 슬롯형입니다. 예약/진행/방문완료/노쇼를 관리하고, 방문완료만 콜 인정·정산표에 자동 반영됩니다. 결제금액은 운영 확인용으로 표시하고, 마사지사 수당·귀케어풀은 숨김 처리했습니다.
A4: 월간 상태 요약 | 이 영역은 항상 위에 고정됩니다
A5: 월 예약건수 | B5: =COUNTIFS($B$14:$B$3113,">="&DATE(YEAR(설정_코스수당!$K$2),MONTH(설정_코스수당!$K$2),1),$B$14:$B$3113,"<"&EDATE(DATE(YEAR(설정_코스수당!$K$2),MONTH(설정_코스수당!$K$2),1),1),$O$14:$O$3113,"<>") -> 0 | D5: 월 방문완료 코스별 | G5: 월간 금액/정산 요약 | J5: 사용법: 아래 날짜 블록을 펼친 뒤 예약/방문완료/노쇼/취소를 입력합니다. 방문완료만 콜 인정 및 정산표에 반영됩니다.
A6: 월 방문완료 콜 | B6: =COUNTIFS($B$14:$B$3113,">="&DATE(YEAR(설정_코스수당!$K$2),MONTH(설정_코스수당!$K$2),1),$B$14:$B$3113,"<"&EDATE(DATE(YEAR(설정_코스수당!$K$2),MONTH(설정_코스수당!$K$2),1),1),$O$14:$O$3113,"방문완료") -> 0 | D6: A코스 | E6: =COUNTIFS($B$14:$B$3113,">="&DATE(YEAR(설정_코스수당!$K$2),MONTH(설정_코스수당!$K$2),1),$B$14:$B$3113,"<"&EDATE(DATE(YEAR(설정_코스수당!$K$2),MONTH(설정_코스수당!$K$2),1),1),$E$14:$E$3113,"A",$O$14:$O$3113,"방문완료") -> 0 | G6: 월 결제합계 | H6: =SUMIFS($J$14:$J$3113,$B$14:$B$3113,">="&DATE(YEAR(설정_코스수당!$K$2),MONTH(설정_코스수당!$K$2),1),$B$14:$B$3113,"<"&EDATE(DATE(YEAR(설정_코스수당!$K$2),MONTH(설정_코스수당!$K$2),1),1),$O$14:$O$3113,"방문완료") -> 0
A7: 월 노쇼 | B7: =COUNTIFS($B$14:$B$3113,">="&DATE(YEAR(설정_코스수당!$K$2),MONTH(설정_코스수당!$K$2),1),$B$14:$B$3113,"<"&EDATE(DATE(YEAR(설정_코스수당!$K$2),MONTH(설정_코스수당!$K$2),1),1),$O$14:$O$3113,"노쇼") -> 0 | D7: B코스 | E7: =COUNTIFS($B$14:$B$3113,">="&DATE(YEAR(설정_코스수당!$K$2),MONTH(설정_코스수당!$K$2),1),$B$14:$B$3113,"<"&EDATE(DATE(YEAR(설정_코스수당!$K$2),MONTH(설정_코스수당!$K$2),1),1),$E$14:$E$3113,"B",$O$14:$O$3113,"방문완료") -> 0 | G7: 월 마사지사 정산 | H7: =SUMIFS($K$14:$K$3113,$B$14:$B$3113,">="&DATE(YEAR(설정_코스수당!$K$2),MONTH(설정_코스수당!$K$2),1),$B$14:$B$3113,"<"&EDATE(DATE(YEAR(설정_코스수당!$K$2),MONTH(설정_코스수당!$K$2),1),1),$O$14:$O$3113,"방문완료")+SUMIFS($L$14:$L$3113,$B$14:$B$3113,">="&DATE(YEAR(설정_코스수당!$K$2),MONTH(설정_코스수당!$K$2),1),$B$14:$B$3113,"<"&EDATE(DATE(YEAR(설정_코스수당!$K$2),MONTH(설정_코스수당!$K$2),1),1),$O$14:$O$3113,"방문완료") -> 0
A8: 월 취소 | B8: =COUNTIFS($B$14:$B$3113,">="&DATE(YEAR(설정_코스수당!$K$2),MONTH(설정_코스수당!$K$2),1),$B$14:$B$3113,"<"&EDATE(DATE(YEAR(설정_코스수당!$K$2),MONTH(설정_코스수당!$K$2),1),1),$O$14:$O$3113,"취소") -> 0 | D8: C코스 | E8: =COUNTIFS($B$14:$B$3113,">="&DATE(YEAR(설정_코스수당!$K$2),MONTH(설정_코스수당!$K$2),1),$B$14:$B$3113,"<"&EDATE(DATE(YEAR(설정_코스수당!$K$2),MONTH(설정_코스수당!$K$2),1),1),$E$14:$E$3113,"C",$O$14:$O$3113,"방문완료") -> 0 | G8: 월 귀케어 풀 | H8: =SUMIFS($M$14:$M$3113,$B$14:$B$3113,">="&DATE(YEAR(설정_코스수당!$K$2),MONTH(설정_코스수당!$K$2),1),$B$14:$B$3113,"<"&EDATE(DATE(YEAR(설정_코스수당!$K$2),MONTH(설정_코스수당!$K$2),1),1),$O$14:$O$3113,"방문완료") -> 0
A9: 월 마사지 담당콜 | B9: =COUNTIFS($B$14:$B$3113,">="&DATE(YEAR(설정_코스수당!$K$2),MONTH(설정_코스수당!$K$2),1),$B$14:$B$3113,"<"&EDATE(DATE(YEAR(설정_코스수당!$K$2),MONTH(설정_코스수당!$K$2),1),1),$G$14:$G$3113,"<>",$O$14:$O$3113,"방문완료")+COUNTIFS($B$14:$B$3113,">="&DATE(YEAR(설정_코스수당!$K$2),MONTH(설정_코스수당!$K$2),1),$B$14:$B$3113,"<"&EDATE(DATE(YEAR(설정_코스수당!$K$2),MONTH(설정_코스수당!$K$2),1),1),$H$14:$H$3113,"<>",$O$14:$O$3113,"방문완료") -> 0 | D9: D코스 | E9: =COUNTIFS($B$14:$B$3113,">="&DATE(YEAR(설정_코스수당!$K$2),MONTH(설정_코스수당!$K$2),1),$B$14:$B$3113,"<"&EDATE(DATE(YEAR(설정_코스수당!$K$2),MONTH(설정_코스수당!$K$2),1),1),$E$14:$E$3113,"D",$O$14:$O$3113,"방문완료") -> 0 | G9: 월 할인합계 | H9: =COUNTIFS($B$14:$B$3113,">="&DATE(YEAR(설정_코스수당!$K$2),MONTH(설정_코스수당!$K$2),1),$B$14:$B$3113,"<"&EDATE(DATE(YEAR(설정_코스수당!$K$2),MONTH(설정_코스수당!$K$2),1),1),$O$14:$O$3113,"방문완료",$P$14:$P$3113,"<>",$P$14:$P$3113,"<>없음")*100000 -> 0
D10: E코스 | E10: =COUNTIFS($B$14:$B$3113,">="&DATE(YEAR(설정_코스수당!$K$2),MONTH(설정_코스수당!$K$2),1),$B$14:$B$3113,"<"&EDATE(DATE(YEAR(설정_코스수당!$K$2),MONTH(설정_코스수당!$K$2),1),1),$E$14:$E$3113,"E",$O$14:$O$3113,"방문완료") -> 0 | G10: 월 지출합계 | H10: =SUM($U$25:$U$32,$U$128:$U$135,$U$231:$U$238,$U$334:$U$341,$U$437:$U$444,$U$540:$U$547,$U$643:$U$650,$U$746:$U$753,$U$849:$U$856,$U$952:$U$959,$U$1055:$U$1062,$U$1158:$U$1165,$U$1261:$U$1268,$U$1364:$U$1371,$U$1467:$U$1474,$U$1570:$U$1577,$U$1673:$U$1680,$U$1776:$U$1783,$U$1879:$U$1886,$U$1982:$U$1989,$U$2085:$U$2092,$U$2188:$U$2195,$U$2291:$U$2298,$U$2394:$U$2401,$U$2497:$U$2504,$U$2600:$U$2607,$U$2703:$U$2710,$U$2806:$U$2813,$U$2909:$U$2916,$U$3012:$U$3019,$U$3115:$U$3122) -> 0
A11: ="계 : "&TEXT(H6-H7-H8-H9-H10,"#,##0")&" 동" -> 계 : 0 동
A12: =IF(1<=DAY(DATE(YEAR(설정_코스수당!$K$2),MONTH(설정_코스수당!$K$2)+1,0)),TEXT(DATE(YEAR(설정_코스수당!$K$2),MONTH(설정_코스수당!$K$2),1),"yyyy-mm-dd")&" | 예약관리 100슬롯","") -> 2026-06-01 | 예약관리 100슬롯
A13: 번호 | B13: 날짜 | C13: 시간 | D13: 방번호 | E13: 코스 | F13: 고객/메모 | G13: 마사지사1 | H13: 마사지사2 | I13: 귀케어담당 | J13: 결제금액 | K13: 마사지사1수당 | L13: 마사지사2수당 | M13: 귀케어풀 | N13: 콜인정 | O13: 예약상태 | P13: 할인구분 | Q13: 결제수단 | R13: 비고 | S13: 확인 | U13: =IF(1<=DAY(DATE(YEAR(설정_코스수당!$K$2),MONTH(설정_코스수당!$K$2)+1,0)),TEXT(DATE(YEAR(설정_코스수당!$K$2),MONTH(설정_코스수당!$K$2),1),"yyyy-mm-dd")&" 일일 상태","") -> 2026-06-01 일일 상태 | W13: 방문완료 코스별
A14: 1 | B14: =IF(1<=DAY(DATE(YEAR(설정_코스수당!$K$2),MONTH(설정_코스수당!$K$2)+1,0)),DATE(YEAR(설정_코스수당!$K$2),MONTH(설정_코스수당!$K$2),1),"") -> 46174 | J14: =IF($O14="방문완료",MAX(0,IFERROR(VLOOKUP($E14,설정_코스수당!$A$6:$H$10,4,FALSE),0)-IF(OR($P14="",$P14="없음"),0,100000)),0) -> 0 | K14: {=IF($O14="방문완료",IFERROR(INDEX(설정_코스수당!$B$15:$F$64,MATCH($G14,설정_코스수당!$A$15:$A$64,0),MATCH($E14&"수당",설정_코스수당!$B$14:$F$14,0)),0),0)} -> 0 | L14: {=IF($O14="방문완료",IF($H14="",0,IFERROR(INDEX(설정_코스수당!$B$15:$F$64,MATCH($H14,설정_코스수당!$A$15:$A$64,0),MATCH($E14&"수당",설정_코스수당!$B$14:$F$14,0)),0)),0)} -> 0 | M14: =IF($O14="방문완료",IFERROR(VLOOKUP($E14,설정_코스수당!$A$6:$H$10,6,FALSE),0),0) -> 0 | N14: =IF($O14="방문완료",1,0) -> 0 | U14: 예약건수 | V14: =IF(1<=DAY(DATE(YEAR(설정_코스수당!$K$2),MONTH(설정_코스수당!$K$2)+1,0)),COUNTIFS($B:$B,DATE(YEAR(설정_코스수당!$K$2),MONTH(설정_코스수당!$K$2),1),$O:$O,"<>"),"") -> 0 | W14: A코스 | X14: =IF(1<=DAY(DATE(YEAR(설정_코스수당!$K$2),MONTH(설정_코스수당!$K$2)+1,0)),COUNTIFS($B:$B,DATE(YEAR(설정_코스수당!$K$2),MONTH(설정_코스수당!$K$2),1),$E:$E,"A",$O:$O,"방문완료"),"") -> 0
A15: 2 | B15: =IF(1<=DAY(DATE(YEAR(설정_코스수당!$K$2),MONTH(설정_코스수당!$K$2)+1,0)),DATE(YEAR(설정_코스수당!$K$2),MONTH(설정_코스수당!$K$2),1),"") -> 46174 | J15: =IF($O15="방문완료",MAX(0,IFERROR(VLOOKUP($E15,설정_코스수당!$A$6:$H$10,4,FALSE),0)-IF(OR($P15="",$P15="없음"),0,100000)),0) -> 0 | K15: {=IF($O15="방문완료",IFERROR(INDEX(설정_코스수당!$B$15:$F$64,MATCH($G15,설정_코스수당!$A$15:$A$64,0),MATCH($E15&"수당",설정_코스수당!$B$14:$F$14,0)),0),0)} -> 0 | L15: {=IF($O15="방문완료",IF($H15="",0,IFERROR(INDEX(설정_코스수당!$B$15:$F$64,MATCH($H15,설정_코스수당!$A$15:$A$64,0),MATCH($E15&"수당",설정_코스수당!$B$14:$F$14,0)),0)),0)} -> 0 | M15: =IF($O15="방문완료",IFERROR(VLOOKUP($E15,설정_코스수당!$A$6:$H$10,6,FALSE),0),0) -> 0 | N15: =IF($O15="방문완료",1,0) -> 0 | U15: 방문완료 | V15: =IF(1<=DAY(DATE(YEAR(설정_코스수당!$K$2),MONTH(설정_코스수당!$K$2)+1,0)),COUNTIFS($B:$B,DATE(YEAR(설정_코스수당!$K$2),MONTH(설정_코스수당!$K$2),1),$O:$O,"방문완료"),"") -> 0 | W15: B코스 | X15: =IF(1<=DAY(DATE(YEAR(설정_코스수당!$K$2),MONTH(설정_코스수당!$K$2)+1,0)),COUNTIFS($B:$B,DATE(YEAR(설정_코스수당!$K$2),MONTH(설정_코스수당!$K$2),1),$E:$E,"B",$O:$O,"방문완료"),"") -> 0
A16: 3 | B16: =IF(1<=DAY(DATE(YEAR(설정_코스수당!$K$2),MONTH(설정_코스수당!$K$2)+1,0)),DATE(YEAR(설정_코스수당!$K$2),MONTH(설정_코스수당!$K$2),1),"") -> 46174 | J16: =IF($O16="방문완료",MAX(0,IFERROR(VLOOKUP($E16,설정_코스수당!$A$6:$H$10,4,FALSE),0)-IF(OR($P16="",$P16="없음"),0,100000)),0) -> 0 | K16: {=IF($O16="방문완료",IFERROR(INDEX(설정_코스수당!$B$15:$F$64,MATCH($G16,설정_코스수당!$A$15:$A$64,0),MATCH($E16&"수당",설정_코스수당!$B$14:$F$14,0)),0),0)} -> 0 | L16: {=IF($O16="방문완료",IF($H16="",0,IFERROR(INDEX(설정_코스수당!$B$15:$F$64,MATCH($H16,설정_코스수당!$A$15:$A$64,0),MATCH($E16&"수당",설정_코스수당!$B$14:$F$14,0)),0)),0)} -> 0 | M16: =IF($O16="방문완료",IFERROR(VLOOKUP($E16,설정_코스수당!$A$6:$H$10,6,FALSE),0),0) -> 0 | N16: =IF($O16="방문완료",1,0) -> 0 | U16: 노쇼/취소 | V16: =IF(1<=DAY(DATE(YEAR(설정_코스수당!$K$2),MONTH(설정_코스수당!$K$2)+1,0)),COUNTIFS($B:$B,DATE(YEAR(설정_코스수당!$K$2),MONTH(설정_코스수당!$K$2),1),$O:$O,"노쇼")&"/"&COUNTIFS($B:$B,DATE(YEAR(설정_코스수당!$K$2),MONTH(설정_코스수당!$K$2),1),$O:$O,"취소"),"") -> 0/0 | W16: C코스 | X16: =IF(1<=DAY(DATE(YEAR(설정_코스수당!$K$2),MONTH(설정_코스수당!$K$2)+1,0)),COUNTIFS($B:$B,DATE(YEAR(설정_코스수당!$K$2),MONTH(설정_코스수당!$K$2),1),$E:$E,"C",$O:$O,"방문완료"),"") -> 0
A17: 4 | B17: =IF(1<=DAY(DATE(YEAR(설정_코스수당!$K$2),MONTH(설정_코스수당!$K$2)+1,0)),DATE(YEAR(설정_코스수당!$K$2),MONTH(설정_코스수당!$K$2),1),"") -> 46174 | J17: =IF($O17="방문완료",MAX(0,IFERROR(VLOOKUP($E17,설정_코스수당!$A$6:$H$10,4,FALSE),0)-IF(OR($P17="",$P17="없음"),0,100000)),0) -> 0 | K17: {=IF($O17="방문완료",IFERROR(INDEX(설정_코스수당!$B$15:$F$64,MATCH($G17,설정_코스수당!$A$15:$A$64,0),MATCH($E17&"수당",설정_코스수당!$B$14:$F$14,0)),0),0)} -> 0 | L17: {=IF($O17="방문완료",IF($H17="",0,IFERROR(INDEX(설정_코스수당!$B$15:$F$64,MATCH($H17,설정_코스수당!$A$15:$A$64,0),MATCH($E17&"수당",설정_코스수당!$B$14:$F$14,0)),0)),0)} -> 0 | M17: =IF($O17="방문완료",IFERROR(VLOOKUP($E17,설정_코스수당!$A$6:$H$10,6,FALSE),0),0) -> 0 | N17: =IF($O17="방문완료",1,0) -> 0 | U17: 결제합계 | V17: =IF(1<=DAY(DATE(YEAR(설정_코스수당!$K$2),MONTH(설정_코스수당!$K$2)+1,0)),SUMIFS($J:$J,$B:$B,DATE(YEAR(설정_코스수당!$K$2),MONTH(설정_코스수당!$K$2),1),$O:$O,"방문완료"),"") -> 0 | W17: D코스 | X17: =IF(1<=DAY(DATE(YEAR(설정_코스수당!$K$2),MONTH(설정_코스수당!$K$2)+1,0)),COUNTIFS($B:$B,DATE(YEAR(설정_코스수당!$K$2),MONTH(설정_코스수당!$K$2),1),$E:$E,"D",$O:$O,"방문완료"),"") -> 0
A18: 5 | B18: =IF(1<=DAY(DATE(YEAR(설정_코스수당!$K$2),MONTH(설정_코스수당!$K$2)+1,0)),DATE(YEAR(설정_코스수당!$K$2),MONTH(설정_코스수당!$K$2),1),"") -> 46174 | J18: =IF($O18="방문완료",MAX(0,IFERROR(VLOOKUP($E18,설정_코스수당!$A$6:$H$10,4,FALSE),0)-IF(OR($P18="",$P18="없음"),0,100000)),0) -> 0 | K18: {=IF($O18="방문완료",IFERROR(INDEX(설정_코스수당!$B$15:$F$64,MATCH($G18,설정_코스수당!$A$15:$A$64,0),MATCH($E18&"수당",설정_코스수당!$B$14:$F$14,0)),0),0)} -> 0 | L18: {=IF($O18="방문완료",IF($H18="",0,IFERROR(INDEX(설정_코스수당!$B$15:$F$64,MATCH($H18,설정_코스수당!$A$15:$A$64,0),MATCH($E18&"수당",설정_코스수당!$B$14:$F$14,0)),0)),0)} -> 0 | M18: =IF($O18="방문완료",IFERROR(VLOOKUP($E18,설정_코스수당!$A$6:$H$10,6,FALSE),0),0) -> 0 | N18: =IF($O18="방문완료",1,0) -> 0 | U18: 마사지사 정산 | V18: =IF(1<=DAY(DATE(YEAR(설정_코스수당!$K$2),MONTH(설정_코스수당!$K$2)+1,0)),SUMIFS($K:$K,$B:$B,DATE(YEAR(설정_코스수당!$K$2),MONTH(설정_코스수당!$K$2),1),$O:$O,"방문완료")+SUMIFS($L:$L,$B:$B,DATE(YEAR(설정_코스수당!$K$2),MONTH(설정_코스수당!$K$2),1),$O:$O,"방문완료"),"") -> 0 | W18: E코스 | X18: =IF(1<=DAY(DATE(YEAR(설정_코스수당!$K$2),MONTH(설정_코스수당!$K$2)+1,0)),COUNTIFS($B:$B,DATE(YEAR(설정_코스수당!$K$2),MONTH(설정_코스수당!$K$2),1),$E:$E,"E",$O:$O,"방문완료"),"") -> 0
A19: 6 | B19: =IF(1<=DAY(DATE(YEAR(설정_코스수당!$K$2),MONTH(설정_코스수당!$K$2)+1,0)),DATE(YEAR(설정_코스수당!$K$2),MONTH(설정_코스수당!$K$2),1),"") -> 46174 | J19: =IF($O19="방문완료",MAX(0,IFERROR(VLOOKUP($E19,설정_코스수당!$A$6:$H$10,4,FALSE),0)-IF(OR($P19="",$P19="없음"),0,100000)),0) -> 0 | K19: {=IF($O19="방문완료",IFERROR(INDEX(설정_코스수당!$B$15:$F$64,MATCH($G19,설정_코스수당!$A$15:$A$64,0),MATCH($E19&"수당",설정_코스수당!$B$14:$F$14,0)),0),0)} -> 0 | L19: {=IF($O19="방문완료",IF($H19="",0,IFERROR(INDEX(설정_코스수당!$B$15:$F$64,MATCH($H19,설정_코스수당!$A$15:$A$64,0),MATCH($E19&"수당",설정_코스수당!$B$14:$F$14,0)),0)),0)} -> 0 | M19: =IF($O19="방문완료",IFERROR(VLOOKUP($E19,설정_코스수당!$A$6:$H$10,6,FALSE),0),0) -> 0 | N19: =IF($O19="방문완료",1,0) -> 0 | U19: 귀케어풀 | V19: =IF(1<=DAY(DATE(YEAR(설정_코스수당!$K$2),MONTH(설정_코스수당!$K$2)+1,0)),SUMIFS($M:$M,$B:$B,DATE(YEAR(설정_코스수당!$K$2),MONTH(설정_코스수당!$K$2),1),$O:$O,"방문완료"),"") -> 0 | W19: 할인건수 | X19: =IF(1<=DAY(DATE(YEAR(설정_코스수당!$K$2),MONTH(설정_코스수당!$K$2)+1,0)),COUNTIFS($B:$B,DATE(YEAR(설정_코스수당!$K$2),MONTH(설정_코스수당!$K$2),1),$O:$O,"방문완료",$P:$P,"<>",$P:$P,"<>없음"),"") -> 0
A20: 7 | B20: =IF(1<=DAY(DATE(YEAR(설정_코스수당!$K$2),MONTH(설정_코스수당!$K$2)+1,0)),DATE(YEAR(설정_코스수당!$K$2),MONTH(설정_코스수당!$K$2),1),"") -> 46174 | J20: =IF($O20="방문완료",MAX(0,IFERROR(VLOOKUP($E20,설정_코스수당!$A$6:$H$10,4,FALSE),0)-IF(OR($P20="",$P20="없음"),0,100000)),0) -> 0 | K20: {=IF($O20="방문완료",IFERROR(INDEX(설정_코스수당!$B$15:$F$64,MATCH($G20,설정_코스수당!$A$15:$A$64,0),MATCH($E20&"수당",설정_코스수당!$B$14:$F$14,0)),0),0)} -> 0 | L20: {=IF($O20="방문완료",IF($H20="",0,IFERROR(INDEX(설정_코스수당!$B$15:$F$64,MATCH($H20,설정_코스수당!$A$15:$A$64,0),MATCH($E20&"수당",설정_코스수당!$B$14:$F$14,0)),0)),0)} -> 0 | M20: =IF($O20="방문완료",IFERROR(VLOOKUP($E20,설정_코스수당!$A$6:$H$10,6,FALSE),0),0) -> 0 | N20: =IF($O20="방문완료",1,0) -> 0 | U20: 할인합계 | V20: =IF(1<=DAY(DATE(YEAR(설정_코스수당!$K$2),MONTH(설정_코스수당!$K$2)+1,0)),COUNTIFS($B:$B,DATE(YEAR(설정_코스수당!$K$2),MONTH(설정_코스수당!$K$2),1),$O:$O,"방문완료",$P:$P,"<>",$P:$P,"<>없음")*100000,"") -> 0 | W20: 마사지사담당 | X20: =IF(1<=DAY(DATE(YEAR(설정_코스수당!$K$2),MONTH(설정_코스수당!$K$2)+1,0)),COUNTIFS($B:$B,DATE(YEAR(설정_코스수당!$K$2),MONTH(설정_코스수당!$K$2),1),$G:$G,"<>",$O:$O,"방문완료")+COUNTIFS($B:$B,DATE(YEAR(설정_코스수당!$K$2),MONTH(설정_코스수당!$K$2),1),$H:$H,"<>",$O:$O,"방문완료"),"") -> 0
A21: 8 | B21: =IF(1<=DAY(DATE(YEAR(설정_코스수당!$K$2),MONTH(설정_코스수당!$K$2)+1,0)),DATE(YEAR(설정_코스수당!$K$2),MONTH(설정_코스수당!$K$2),1),"") -> 46174 | J21: =IF($O21="방문완료",MAX(0,IFERROR(VLOOKUP($E21,설정_코스수당!$A$6:$H$10,4,FALSE),0)-IF(OR($P21="",$P21="없음"),0,100000)),0) -> 0 | K21: {=IF($O21="방문완료",IFERROR(INDEX(설정_코스수당!$B$15:$F$64,MATCH($G21,설정_코스수당!$A$15:$A$64,0),MATCH($E21&"수당",설정_코스수당!$B$14:$F$14,0)),0),0)} -> 0 | L21: {=IF($O21="방문완료",IF($H21="",0,IFERROR(INDEX(설정_코스수당!$B$15:$F$64,MATCH($H21,설정_코스수당!$A$15:$A$64,0),MATCH($E21&"수당",설정_코스수당!$B$14:$F$14,0)),0)),0)} -> 0 | M21: =IF($O21="방문완료",IFERROR(VLOOKUP($E21,설정_코스수당!$A$6:$H$10,6,FALSE),0),0) -> 0 | N21: =IF($O21="방문완료",1,0) -> 0 | U21: 지출합계 | V21: =IF(1<=DAY(DATE(YEAR(설정_코스수당!$K$2),MONTH(설정_코스수당!$K$2)+1,0)),SUM($U$25:$U$32),"") -> 0 | W21: =IF(1<=DAY(DATE(YEAR(설정_코스수당!$K$2),MONTH(설정_코스수당!$K$2)+1,0)),"계 : "&TEXT(V17-V18-V19-V20-V21,"#,##0")&" 동","") -> 계 : 0 동
A22: 9 | B22: =IF(1<=DAY(DATE(YEAR(설정_코스수당!$K$2),MONTH(설정_코스수당!$K$2)+1,0)),DATE(YEAR(설정_코스수당!$K$2),MONTH(설정_코스수당!$K$2),1),"") -> 46174 | J22: =IF($O22="방문완료",MAX(0,IFERROR(VLOOKUP($E22,설정_코스수당!$A$6:$H$10,4,FALSE),0)-IF(OR($P22="",$P22="없음"),0,100000)),0) -> 0 | K22: {=IF($O22="방문완료",IFERROR(INDEX(설정_코스수당!$B$15:$F$64,MATCH($G22,설정_코스수당!$A$15:$A$64,0),MATCH($E22&"수당",설정_코스수당!$B$14:$F$14,0)),0),0)} -> 0 | L22: {=IF($O22="방문완료",IF($H22="",0,IFERROR(INDEX(설정_코스수당!$B$15:$F$64,MATCH($H22,설정_코스수당!$A$15:$A$64,0),MATCH($E22&"수당",설정_코스수당!$B$14:$F$14,0)),0)),0)} -> 0 | M22: =IF($O22="방문완료",IFERROR(VLOOKUP($E22,설정_코스수당!$A$6:$H$10,6,FALSE),0),0) -> 0 | N22: =IF($O22="방문완료",1,0) -> 0
A23: 10 | B23: =IF(1<=DAY(DATE(YEAR(설정_코스수당!$K$2),MONTH(설정_코스수당!$K$2)+1,0)),DATE(YEAR(설정_코스수당!$K$2),MONTH(설정_코스수당!$K$2),1),"") -> 46174 | J23: =IF($O23="방문완료",MAX(0,IFERROR(VLOOKUP($E23,설정_코스수당!$A$6:$H$10,4,FALSE),0)-IF(OR($P23="",$P23="없음"),0,100000)),0) -> 0 | K23: {=IF($O23="방문완료",IFERROR(INDEX(설정_코스수당!$B$15:$F$64,MATCH($G23,설정_코스수당!$A$15:$A$64,0),MATCH($E23&"수당",설정_코스수당!$B$14:$F$14,0)),0),0)} -> 0 | L23: {=IF($O23="방문완료",IF($H23="",0,IFERROR(INDEX(설정_코스수당!$B$15:$F$64,MATCH($H23,설정_코스수당!$A$15:$A$64,0),MATCH($E23&"수당",설정_코스수당!$B$14:$F$14,0)),0)),0)} -> 0 | M23: =IF($O23="방문완료",IFERROR(VLOOKUP($E23,설정_코스수당!$A$6:$H$10,6,FALSE),0),0) -> 0 | N23: =IF($O23="방문완료",1,0) -> 0 | U23: 지출 입력
A24: 11 | B24: =IF(1<=DAY(DATE(YEAR(설정_코스수당!$K$2),MONTH(설정_코스수당!$K$2)+1,0)),DATE(YEAR(설정_코스수당!$K$2),MONTH(설정_코스수당!$K$2),1),"") -> 46174 | J24: =IF($O24="방문완료",MAX(0,IFERROR(VLOOKUP($E24,설정_코스수당!$A$6:$H$10,4,FALSE),0)-IF(OR($P24="",$P24="없음"),0,100000)),0) -> 0 | K24: {=IF($O24="방문완료",IFERROR(INDEX(설정_코스수당!$B$15:$F$64,MATCH($G24,설정_코스수당!$A$15:$A$64,0),MATCH($E24&"수당",설정_코스수당!$B$14:$F$14,0)),0),0)} -> 0 | L24: {=IF($O24="방문완료",IF($H24="",0,IFERROR(INDEX(설정_코스수당!$B$15:$F$64,MATCH($H24,설정_코스수당!$A$15:$A$64,0),MATCH($E24&"수당",설정_코스수당!$B$14:$F$14,0)),0)),0)} -> 0 | M24: =IF($O24="방문완료",IFERROR(VLOOKUP($E24,설정_코스수당!$A$6:$H$10,6,FALSE),0),0) -> 0 | N24: =IF($O24="방문완료",1,0) -> 0 | U24: 지출금액 | V24: 내용 | W24: 담당자 | X24: 비고
A25: 12 | B25: =IF(1<=DAY(DATE(YEAR(설정_코스수당!$K$2),MONTH(설정_코스수당!$K$2)+1,0)),DATE(YEAR(설정_코스수당!$K$2),MONTH(설정_코스수당!$K$2),1),"") -> 46174 | J25: =IF($O25="방문완료",MAX(0,IFERROR(VLOOKUP($E25,설정_코스수당!$A$6:$H$10,4,FALSE),0)-IF(OR($P25="",$P25="없음"),0,100000)),0) -> 0 | K25: {=IF($O25="방문완료",IFERROR(INDEX(설정_코스수당!$B$15:$F$64,MATCH($G25,설정_코스수당!$A$15:$A$64,0),MATCH($E25&"수당",설정_코스수당!$B$14:$F$14,0)),0),0)} -> 0 | L25: {=IF($O25="방문완료",IF($H25="",0,IFERROR(INDEX(설정_코스수당!$B$15:$F$64,MATCH($H25,설정_코스수당!$A$15:$A$64,0),MATCH($E25&"수당",설정_코스수당!$B$14:$F$14,0)),0)),0)} -> 0 | M25: =IF($O25="방문완료",IFERROR(VLOOKUP($E25,설정_코스수당!$A$6:$H$10,6,FALSE),0),0) -> 0 | N25: =IF($O25="방문완료",1,0) -> 0
A26: 13 | B26: =IF(1<=DAY(DATE(YEAR(설정_코스수당!$K$2),MONTH(설정_코스수당!$K$2)+1,0)),DATE(YEAR(설정_코스수당!$K$2),MONTH(설정_코스수당!$K$2),1),"") -> 46174 | J26: =IF($O26="방문완료",MAX(0,IFERROR(VLOOKUP($E26,설정_코스수당!$A$6:$H$10,4,FALSE),0)-IF(OR($P26="",$P26="없음"),0,100000)),0) -> 0 | K26: {=IF($O26="방문완료",IFERROR(INDEX(설정_코스수당!$B$15:$F$64,MATCH($G26,설정_코스수당!$A$15:$A$64,0),MATCH($E26&"수당",설정_코스수당!$B$14:$F$14,0)),0),0)} -> 0 | L26: {=IF($O26="방문완료",IF($H26="",0,IFERROR(INDEX(설정_코스수당!$B$15:$F$64,MATCH($H26,설정_코스수당!$A$15:$A$64,0),MATCH($E26&"수당",설정_코스수당!$B$14:$F$14,0)),0)),0)} -> 0 | M26: =IF($O26="방문완료",IFERROR(VLOOKUP($E26,설정_코스수당!$A$6:$H$10,6,FALSE),0),0) -> 0 | N26: =IF($O26="방문완료",1,0) -> 0
A27: 14 | B27: =IF(1<=DAY(DATE(YEAR(설정_코스수당!$K$2),MONTH(설정_코스수당!$K$2)+1,0)),DATE(YEAR(설정_코스수당!$K$2),MONTH(설정_코스수당!$K$2),1),"") -> 46174 | J27: =IF($O27="방문완료",MAX(0,IFERROR(VLOOKUP($E27,설정_코스수당!$A$6:$H$10,4,FALSE),0)-IF(OR($P27="",$P27="없음"),0,100000)),0) -> 0 | K27: {=IF($O27="방문완료",IFERROR(INDEX(설정_코스수당!$B$15:$F$64,MATCH($G27,설정_코스수당!$A$15:$A$64,0),MATCH($E27&"수당",설정_코스수당!$B$14:$F$14,0)),0),0)} -> 0 | L27: {=IF($O27="방문완료",IF($H27="",0,IFERROR(INDEX(설정_코스수당!$B$15:$F$64,MATCH($H27,설정_코스수당!$A$15:$A$64,0),MATCH($E27&"수당",설정_코스수당!$B$14:$F$14,0)),0)),0)} -> 0 | M27: =IF($O27="방문완료",IFERROR(VLOOKUP($E27,설정_코스수당!$A$6:$H$10,6,FALSE),0),0) -> 0 | N27: =IF($O27="방문완료",1,0) -> 0
A28: 15 | B28: =IF(1<=DAY(DATE(YEAR(설정_코스수당!$K$2),MONTH(설정_코스수당!$K$2)+1,0)),DATE(YEAR(설정_코스수당!$K$2),MONTH(설정_코스수당!$K$2),1),"") -> 46174 | J28: =IF($O28="방문완료",MAX(0,IFERROR(VLOOKUP($E28,설정_코스수당!$A$6:$H$10,4,FALSE),0)-IF(OR($P28="",$P28="없음"),0,100000)),0) -> 0 | K28: {=IF($O28="방문완료",IFERROR(INDEX(설정_코스수당!$B$15:$F$64,MATCH($G28,설정_코스수당!$A$15:$A$64,0),MATCH($E28&"수당",설정_코스수당!$B$14:$F$14,0)),0),0)} -> 0 | L28: {=IF($O28="방문완료",IF($H28="",0,IFERROR(INDEX(설정_코스수당!$B$15:$F$64,MATCH($H28,설정_코스수당!$A$15:$A$64,0),MATCH($E28&"수당",설정_코스수당!$B$14:$F$14,0)),0)),0)} -> 0 | M28: =IF($O28="방문완료",IFERROR(VLOOKUP($E28,설정_코스수당!$A$6:$H$10,6,FALSE),0),0) -> 0 | N28: =IF($O28="방문완료",1,0) -> 0
A29: 16 | B29: =IF(1<=DAY(DATE(YEAR(설정_코스수당!$K$2),MONTH(설정_코스수당!$K$2)+1,0)),DATE(YEAR(설정_코스수당!$K$2),MONTH(설정_코스수당!$K$2),1),"") -> 46174 | J29: =IF($O29="방문완료",MAX(0,IFERROR(VLOOKUP($E29,설정_코스수당!$A$6:$H$10,4,FALSE),0)-IF(OR($P29="",$P29="없음"),0,100000)),0) -> 0 | K29: {=IF($O29="방문완료",IFERROR(INDEX(설정_코스수당!$B$15:$F$64,MATCH($G29,설정_코스수당!$A$15:$A$64,0),MATCH($E29&"수당",설정_코스수당!$B$14:$F$14,0)),0),0)} -> 0 | L29: {=IF($O29="방문완료",IF($H29="",0,IFERROR(INDEX(설정_코스수당!$B$15:$F$64,MATCH($H29,설정_코스수당!$A$15:$A$64,0),MATCH($E29&"수당",설정_코스수당!$B$14:$F$14,0)),0)),0)} -> 0 | M29: =IF($O29="방문완료",IFERROR(VLOOKUP($E29,설정_코스수당!$A$6:$H$10,6,FALSE),0),0) -> 0 | N29: =IF($O29="방문완료",1,0) -> 0
A30: 17 | B30: =IF(1<=DAY(DATE(YEAR(설정_코스수당!$K$2),MONTH(설정_코스수당!$K$2)+1,0)),DATE(YEAR(설정_코스수당!$K$2),MONTH(설정_코스수당!$K$2),1),"") -> 46174 | J30: =IF($O30="방문완료",MAX(0,IFERROR(VLOOKUP($E30,설정_코스수당!$A$6:$H$10,4,FALSE),0)-IF(OR($P30="",$P30="없음"),0,100000)),0) -> 0 | K30: {=IF($O30="방문완료",IFERROR(INDEX(설정_코스수당!$B$15:$F$64,MATCH($G30,설정_코스수당!$A$15:$A$64,0),MATCH($E30&"수당",설정_코스수당!$B$14:$F$14,0)),0),0)} -> 0 | L30: {=IF($O30="방문완료",IF($H30="",0,IFERROR(INDEX(설정_코스수당!$B$15:$F$64,MATCH($H30,설정_코스수당!$A$15:$A$64,0),MATCH($E30&"수당",설정_코스수당!$B$14:$F$14,0)),0)),0)} -> 0 | M30: =IF($O30="방문완료",IFERROR(VLOOKUP($E30,설정_코스수당!$A$6:$H$10,6,FALSE),0),0) -> 0 | N30: =IF($O30="방문완료",1,0) -> 0
A31: 18 | B31: =IF(1<=DAY(DATE(YEAR(설정_코스수당!$K$2),MONTH(설정_코스수당!$K$2)+1,0)),DATE(YEAR(설정_코스수당!$K$2),MONTH(설정_코스수당!$K$2),1),"") -> 46174 | J31: =IF($O31="방문완료",MAX(0,IFERROR(VLOOKUP($E31,설정_코스수당!$A$6:$H$10,4,FALSE),0)-IF(OR($P31="",$P31="없음"),0,100000)),0) -> 0 | K31: {=IF($O31="방문완료",IFERROR(INDEX(설정_코스수당!$B$15:$F$64,MATCH($G31,설정_코스수당!$A$15:$A$64,0),MATCH($E31&"수당",설정_코스수당!$B$14:$F$14,0)),0),0)} -> 0 | L31: {=IF($O31="방문완료",IF($H31="",0,IFERROR(INDEX(설정_코스수당!$B$15:$F$64,MATCH($H31,설정_코스수당!$A$15:$A$64,0),MATCH($E31&"수당",설정_코스수당!$B$14:$F$14,0)),0)),0)} -> 0 | M31: =IF($O31="방문완료",IFERROR(VLOOKUP($E31,설정_코스수당!$A$6:$H$10,6,FALSE),0),0) -> 0 | N31: =IF($O31="방문완료",1,0) -> 0
A32: 19 | B32: =IF(1<=DAY(DATE(YEAR(설정_코스수당!$K$2),MONTH(설정_코스수당!$K$2)+1,0)),DATE(YEAR(설정_코스수당!$K$2),MONTH(설정_코스수당!$K$2),1),"") -> 46174 | J32: =IF($O32="방문완료",MAX(0,IFERROR(VLOOKUP($E32,설정_코스수당!$A$6:$H$10,4,FALSE),0)-IF(OR($P32="",$P32="없음"),0,100000)),0) -> 0 | K32: {=IF($O32="방문완료",IFERROR(INDEX(설정_코스수당!$B$15:$F$64,MATCH($G32,설정_코스수당!$A$15:$A$64,0),MATCH($E32&"수당",설정_코스수당!$B$14:$F$14,0)),0),0)} -> 0 | L32: {=IF($O32="방문완료",IF($H32="",0,IFERROR(INDEX(설정_코스수당!$B$15:$F$64,MATCH($H32,설정_코스수당!$A$15:$A$64,0),MATCH($E32&"수당",설정_코스수당!$B$14:$F$14,0)),0)),0)} -> 0 | M32: =IF($O32="방문완료",IFERROR(VLOOKUP($E32,설정_코스수당!$A$6:$H$10,6,FALSE),0),0) -> 0 | N32: =IF($O32="방문완료",1,0) -> 0
A33: 20 | B33: =IF(1<=DAY(DATE(YEAR(설정_코스수당!$K$2),MONTH(설정_코스수당!$K$2)+1,0)),DATE(YEAR(설정_코스수당!$K$2),MONTH(설정_코스수당!$K$2),1),"") -> 46174 | J33: =IF($O33="방문완료",MAX(0,IFERROR(VLOOKUP($E33,설정_코스수당!$A$6:$H$10,4,FALSE),0)-IF(OR($P33="",$P33="없음"),0,100000)),0) -> 0 | K33: {=IF($O33="방문완료",IFERROR(INDEX(설정_코스수당!$B$15:$F$64,MATCH($G33,설정_코스수당!$A$15:$A$64,0),MATCH($E33&"수당",설정_코스수당!$B$14:$F$14,0)),0),0)} -> 0 | L33: {=IF($O33="방문완료",IF($H33="",0,IFERROR(INDEX(설정_코스수당!$B$15:$F$64,MATCH($H33,설정_코스수당!$A$15:$A$64,0),MATCH($E33&"수당",설정_코스수당!$B$14:$F$14,0)),0)),0)} -> 0 | M33: =IF($O33="방문완료",IFERROR(VLOOKUP($E33,설정_코스수당!$A$6:$H$10,6,FALSE),0),0) -> 0 | N33: =IF($O33="방문완료",1,0) -> 0
A34: 21 | B34: =IF(1<=DAY(DATE(YEAR(설정_코스수당!$K$2),MONTH(설정_코스수당!$K$2)+1,0)),DATE(YEAR(설정_코스수당!$K$2),MONTH(설정_코스수당!$K$2),1),"") -> 46174 | J34: =IF($O34="방문완료",MAX(0,IFERROR(VLOOKUP($E34,설정_코스수당!$A$6:$H$10,4,FALSE),0)-IF(OR($P34="",$P34="없음"),0,100000)),0) -> 0 | K34: {=IF($O34="방문완료",IFERROR(INDEX(설정_코스수당!$B$15:$F$64,MATCH($G34,설정_코스수당!$A$15:$A$64,0),MATCH($E34&"수당",설정_코스수당!$B$14:$F$14,0)),0),0)} -> 0 | L34: {=IF($O34="방문완료",IF($H34="",0,IFERROR(INDEX(설정_코스수당!$B$15:$F$64,MATCH($H34,설정_코스수당!$A$15:$A$64,0),MATCH($E34&"수당",설정_코스수당!$B$14:$F$14,0)),0)),0)} -> 0 | M34: =IF($O34="방문완료",IFERROR(VLOOKUP($E34,설정_코스수당!$A$6:$H$10,6,FALSE),0),0) -> 0 | N34: =IF($O34="방문완료",1,0) -> 0
A35: 22 | B35: =IF(1<=DAY(DATE(YEAR(설정_코스수당!$K$2),MONTH(설정_코스수당!$K$2)+1,0)),DATE(YEAR(설정_코스수당!$K$2),MONTH(설정_코스수당!$K$2),1),"") -> 46174 | J35: =IF($O35="방문완료",MAX(0,IFERROR(VLOOKUP($E35,설정_코스수당!$A$6:$H$10,4,FALSE),0)-IF(OR($P35="",$P35="없음"),0,100000)),0) -> 0 | K35: {=IF($O35="방문완료",IFERROR(INDEX(설정_코스수당!$B$15:$F$64,MATCH($G35,설정_코스수당!$A$15:$A$64,0),MATCH($E35&"수당",설정_코스수당!$B$14:$F$14,0)),0),0)} -> 0 | L35: {=IF($O35="방문완료",IF($H35="",0,IFERROR(INDEX(설정_코스수당!$B$15:$F$64,MATCH($H35,설정_코스수당!$A$15:$A$64,0),MATCH($E35&"수당",설정_코스수당!$B$14:$F$14,0)),0)),0)} -> 0 | M35: =IF($O35="방문완료",IFERROR(VLOOKUP($E35,설정_코스수당!$A$6:$H$10,6,FALSE),0),0) -> 0 | N35: =IF($O35="방문완료",1,0) -> 0
A36: 23 | B36: =IF(1<=DAY(DATE(YEAR(설정_코스수당!$K$2),MONTH(설정_코스수당!$K$2)+1,0)),DATE(YEAR(설정_코스수당!$K$2),MONTH(설정_코스수당!$K$2),1),"") -> 46174 | J36: =IF($O36="방문완료",MAX(0,IFERROR(VLOOKUP($E36,설정_코스수당!$A$6:$H$10,4,FALSE),0)-IF(OR($P36="",$P36="없음"),0,100000)),0) -> 0 | K36: {=IF($O36="방문완료",IFERROR(INDEX(설정_코스수당!$B$15:$F$64,MATCH($G36,설정_코스수당!$A$15:$A$64,0),MATCH($E36&"수당",설정_코스수당!$B$14:$F$14,0)),0),0)} -> 0 | L36: {=IF($O36="방문완료",IF($H36="",0,IFERROR(INDEX(설정_코스수당!$B$15:$F$64,MATCH($H36,설정_코스수당!$A$15:$A$64,0),MATCH($E36&"수당",설정_코스수당!$B$14:$F$14,0)),0)),0)} -> 0 | M36: =IF($O36="방문완료",IFERROR(VLOOKUP($E36,설정_코스수당!$A$6:$H$10,6,FALSE),0),0) -> 0 | N36: =IF($O36="방문완료",1,0) -> 0
... A113: 100 | B113: =IF(1<=DAY(DATE(YEAR(설정_코스수당!$K$2),MONTH(설정_코스수당!$K$2)+1,0)),DATE(YEAR(설정_코스수당!$K$2),MONTH(설정_코스수당!$K$2),1),"") -> 46174 | J113: =IF($O113="방문완료",MAX(0,IFERROR(VLOOKUP($E113,설정_코스수당!$A$6:$H$10,4,FALSE),0)-IF(OR($P113="",$P113="없음"),0,100000)),0) -> 0 | K113: {=IF($O113="방문완료",IFERROR(INDEX(설정_코스수당!$B$15:$F$64,MATCH($G113,설정_코스수당!$A$15:$A$64,0),MATCH($E113&"수당",설정_코스수당!$B$14:$F$14,0)),0),0)} -> 0 | L113: {=IF($O113="방문완료",IF($H113="",0,IFERROR(INDEX(설정_코스수당!$B$15:$F$64,MATCH($H113,설정_코스수당!$A$15:$A$64,0),MATCH($E113&"수당",설정_코스수당!$B$14:$F$14,0)),0)),0)} -> 0 | M113: =IF($O113="방문완료",IFERROR(VLOOKUP($E113,설정_코스수당!$A$6:$H$10,6,FALSE),0),0) -> 0 | N113: =IF($O113="방문완료",1,0) -> 0
A114: 일일 입력 끝 | J114: =IF($O114="방문완료",MAX(0,IFERROR(VLOOKUP($E114,설정_코스수당!$A$6:$H$10,4,FALSE),0)-IF(OR($P114="",$P114="없음"),0,100000)),0) -> 0
A115: =IF(2<=DAY(DATE(YEAR(설정_코스수당!$K$2),MONTH(설정_코스수당!$K$2)+1,0)),TEXT(DATE(YEAR(설정_코스수당!$K$2),MONTH(설정_코스수당!$K$2),2),"yyyy-mm-dd")&" | 예약관리 100슬롯","") -> 2026-06-02 | 예약관리 100슬롯
A116: 번호 | B116: 날짜 | C116: 시간 | D116: 방번호 | E116: 코스 | F116: 고객/메모 | G116: 마사지사1 | H116: 마사지사2 | I116: 귀케어담당 | J116: 결제금액 | K116: 마사지사1수당 | L116: 마사지사2수당 | M116: 귀케어풀 | N116: 콜인정 | O116: 예약상태 | P116: 할인구분 | Q116: 결제수단 | R116: 비고 | S116: 확인 | U116: =IF(2<=DAY(DATE(YEAR(설정_코스수당!$K$2),MONTH(설정_코스수당!$K$2)+1,0)),TEXT(DATE(YEAR(설정_코스수당!$K$2),MONTH(설정_코스수당!$K$2),2),"yyyy-mm-dd")&" 일일 상태","") -> 2026-06-02 일일 상태 | W116: 방문완료 코스별
A117: 1 | B117: =IF(2<=DAY(DATE(YEAR(설정_코스수당!$K$2),MONTH(설정_코스수당!$K$2)+1,0)),DATE(YEAR(설정_코스수당!$K$2),MONTH(설정_코스수당!$K$2),2),"") -> 46175 | J117: =IF($O117="방문완료",MAX(0,IFERROR(VLOOKUP($E117,설정_코스수당!$A$6:$H$10,4,FALSE),0)-IF(OR($P117="",$P117="없음"),0,100000)),0) -> 0 | K117: {=IF($O117="방문완료",IFERROR(INDEX(설정_코스수당!$B$15:$F$64,MATCH($G117,설정_코스수당!$A$15:$A$64,0),MATCH($E117&"수당",설정_코스수당!$B$14:$F$14,0)),0),0)} -> 0 | L117: {=IF($O117="방문완료",IF($H117="",0,IFERROR(INDEX(설정_코스수당!$B$15:$F$64,MATCH($H117,설정_코스수당!$A$15:$A$64,0),MATCH($E117&"수당",설정_코스수당!$B$14:$F$14,0)),0)),0)} -> 0 | M117: =IF($O117="방문완료",IFERROR(VLOOKUP($E117,설정_코스수당!$A$6:$H$10,6,FALSE),0),0) -> 0 | N117: =IF($O117="방문완료",1,0) -> 0 | U117: 예약건수 | V117: =IF(2<=DAY(DATE(YEAR(설정_코스수당!$K$2),MONTH(설정_코스수당!$K$2)+1,0)),COUNTIFS($B:$B,DATE(YEAR(설정_코스수당!$K$2),MONTH(설정_코스수당!$K$2),2),$O:$O,"<>"),"") -> 0 | W117: A코스 | X117: =IF(2<=DAY(DATE(YEAR(설정_코스수당!$K$2),MONTH(설정_코스수당!$K$2)+1,0)),COUNTIFS($B:$B,DATE(YEAR(설정_코스수당!$K$2),MONTH(설정_코스수당!$K$2),2),$E:$E,"A",$O:$O,"방문완료"),"") -> 0
...

Sheet 웨이터리스트
A1: GANGNAM SPA 웨이터용 객실 현황판
A2: 실시간콜입력에 시간 · 방번호 · 코스 · 마사지사1 · 예약상태 입력 → 이 화면 자동 반영
A4: 사용중 | B4: 예약 | C4: 청소중 | D4: 종료확인 | E4: 빈방 | F4: 곧 종료
A5: =COUNTIF($B$9:$B$19,"사용중") -> 0 | B5: =COUNTIF($B$9:$B$19,"예약") -> 0 | C5: =COUNTIF($B$9:$B$19,"청소중") -> 0 | D5: =COUNTIF($B$9:$B$19,"종료확인") -> 0 | E5: =COUNTIF($B$9:$B$19,"빈방") -> 11 | F5: =COUNTIFS($B$9:$B$19,"사용중",$F$9:$F$19,"<=10",$F$9:$F$19,">=0") -> 0
A8: 방번호 | B8: 상태 | C8: 코스 | D8: 담당 | E8: 시작 | F8: 남은분 | G8: 종료예정 | H8: 웨이터 안내 | I8: 메모 | J8: 기본상태 | K8: 코스시간 | L8: 시작DT
A9: 101 호실 | B9: =IF(AND($J9="사용중",$F9=0),"종료확인",$J9) -> 빈방 | C9: =IF($J9="빈방","",IFERROR(LOOKUP(2,1/((실시간콜입력!$D$14:$D$3204=$A9)*((실시간콜입력!$O$14:$O$3204="사용중")+(실시간콜입력!$O$14:$O$3204="청소중")+(실시간콜입력!$O$14:$O$3204="예약"))),실시간콜입력!$E$14:$E$3204),"")) | D9: =IF($J9="빈방","",IFERROR(LOOKUP(2,1/((실시간콜입력!$D$14:$D$3204=$A9)*((실시간콜입력!$O$14:$O$3204="사용중")+(실시간콜입력!$O$14:$O$3204="청소중")+(실시간콜입력!$O$14:$O$3204="예약"))),실시간콜입력!$G$14:$G$3204),"")&IF(IFERROR(LOOKUP(2,1/((실시간콜입력!$D$14:$D$3204=$A9)*((실시간콜입력!$O$14:$O$3204="사용중")+(실시간콜입력!$O$14:$O$3204="청소중")+(실시간콜입력!$O$14:$O$3204="예약"))),실시간콜입력!$H$14:$H$3204),"")<>""," / "&IFERROR(LOOKUP(2,1/((실시간콜입력!$D$14:$D$3204=$A9)*((실시간콜입력!$O$14:$O$3204="사용중")+(실시간콜입력!$O$14:$O$3204="청소중")+(실시간콜입력!$O$14:$O$3204="예약"))),실시간콜입력!$H$14:$H$3204),""),"")&IF(IFERROR(LOOKUP(2,1/((실시간콜입력!$D$14:$D$3204=$A9)*((실시간콜입력!$O$14:$O$3204="사용중")+(실시간콜입력!$O$14:$O$3204="청소중")+(실시간콜입력!$O$14:$O$3204="예약"))),실시간콜입력!$I$14:$I$3204),"")<>""," / "&IFERROR(LOOKUP(2,1/((실시간콜입력!$D$14:$D$3204=$A9)*((실시간콜입력!$O$14:$O$3204="사용중")+(실시간콜입력!$O$14:$O$3204="청소중")+(실시간콜입력!$O$14:$O$3204="예약"))),실시간콜입력!$I$14:$I$3204),""),"")) | E9: =IF($J9="빈방","",IFERROR(TIMEVALUE(IFERROR(LOOKUP(2,1/((실시간콜입력!$D$14:$D$3204=$A9)*((실시간콜입력!$O$14:$O$3204="사용중")+(실시간콜입력!$O$14:$O$3204="청소중")+(실시간콜입력!$O$14:$O$3204="예약"))),실시간콜입력!$C$14:$C$3204),"")),IFERROR(LOOKUP(2,1/((실시간콜입력!$D$14:$D$3204=$A9)*((실시간콜입력!$O$14:$O$3204="사용중")+(실시간콜입력!$O$14:$O$3204="청소중")+(실시간콜입력!$O$14:$O$3204="예약"))),실시간콜입력!$C$14:$C$3204),""))) | F9: =IF($J9<>"사용중","",MAX(0,ROUND((($L9+$K9/1440)-NOW())*1440,0))) | G9: =IF($J9="사용중",$E9+$K9/1440,"") | H9: =IF($B9="빈방","입실 가능",IF($B9="청소중","청소 진행",IF($B9="예약","예약 대기",IF($B9="종료확인","종료 확인 필요",$F9&"분 남음")))) -> 입실 가능 | J9: =IFERROR(LOOKUP(2,1/((실시간콜입력!$D$14:$D$3204=$A9)*((실시간콜입력!$O$14:$O$3204="사용중")+(실시간콜입력!$O$14:$O$3204="청소중")+(실시간콜입력!$O$14:$O$3204="예약"))),실시간콜입력!$O$14:$O$3204),"빈방") -> 빈방 | K9: {=IFERROR(INDEX(TV설정!$E$4:$E$8,MATCH($C9,TV설정!$D$4:$D$8,0)),60)} -> 60 | L9: =IF($E9="","",IF($E9<TIME(3,0,0),IF(MOD(NOW(),1)<TIME(3,0,0),TODAY()+$E9,TODAY()+1+$E9),TODAY()+$E9))
A10: 102 호실 | B10: =IF(AND($J10="사용중",$F10=0),"종료확인",$J10) -> 빈방 | C10: =IF($J10="빈방","",IFERROR(LOOKUP(2,1/((실시간콜입력!$D$14:$D$3204=$A10)*((실시간콜입력!$O$14:$O$3204="사용중")+(실시간콜입력!$O$14:$O$3204="청소중")+(실시간콜입력!$O$14:$O$3204="예약"))),실시간콜입력!$E$14:$E$3204),"")) | D10: =IF($J10="빈방","",IFERROR(LOOKUP(2,1/((실시간콜입력!$D$14:$D$3204=$A10)*((실시간콜입력!$O$14:$O$3204="사용중")+(실시간콜입력!$O$14:$O$3204="청소중")+(실시간콜입력!$O$14:$O$3204="예약"))),실시간콜입력!$G$14:$G$3204),"")&IF(IFERROR(LOOKUP(2,1/((실시간콜입력!$D$14:$D$3204=$A10)*((실시간콜입력!$O$14:$O$3204="사용중")+(실시간콜입력!$O$14:$O$3204="청소중")+(실시간콜입력!$O$14:$O$3204="예약"))),실시간콜입력!$H$14:$H$3204),"")<>""," / "&IFERROR(LOOKUP(2,1/((실시간콜입력!$D$14:$D$3204=$A10)*((실시간콜입력!$O$14:$O$3204="사용중")+(실시간콜입력!$O$14:$O$3204="청소중")+(실시간콜입력!$O$14:$O$3204="예약"))),실시간콜입력!$H$14:$H$3204),""),"")&IF(IFERROR(LOOKUP(2,1/((실시간콜입력!$D$14:$D$3204=$A10)*((실시간콜입력!$O$14:$O$3204="사용중")+(실시간콜입력!$O$14:$O$3204="청소중")+(실시간콜입력!$O$14:$O$3204="예약"))),실시간콜입력!$I$14:$I$3204),"")<>""," / "&IFERROR(LOOKUP(2,1/((실시간콜입력!$D$14:$D$3204=$A10)*((실시간콜입력!$O$14:$O$3204="사용중")+(실시간콜입력!$O$14:$O$3204="청소중")+(실시간콜입력!$O$14:$O$3204="예약"))),실시간콜입력!$I$14:$I$3204),""),"")) | E10: =IF($J10="빈방","",IFERROR(TIMEVALUE(IFERROR(LOOKUP(2,1/((실시간콜입력!$D$14:$D$3204=$A10)*((실시간콜입력!$O$14:$O$3204="사용중")+(실시간콜입력!$O$14:$O$3204="청소중")+(실시간콜입력!$O$14:$O$3204="예약"))),실시간콜입력!$C$14:$C$3204),"")),IFERROR(LOOKUP(2,1/((실시간콜입력!$D$14:$D$3204=$A10)*((실시간콜입력!$O$14:$O$3204="사용중")+(실시간콜입력!$O$14:$O$3204="청소중")+(실시간콜입력!$O$14:$O$3204="예약"))),실시간콜입력!$C$14:$C$3204),""))) | F10: =IF($J10<>"사용중","",MAX(0,ROUND((($L10+$K10/1440)-NOW())*1440,0))) | G10: =IF($J10="사용중",$E10+$K10/1440,"") | H10: =IF($B10="빈방","입실 가능",IF($B10="청소중","청소 진행",IF($B10="예약","예약 대기",IF($B10="종료확인","종료 확인 필요",$F10&"분 남음")))) -> 입실 가능 | J10: =IFERROR(LOOKUP(2,1/((실시간콜입력!$D$14:$D$3204=$A10)*((실시간콜입력!$O$14:$O$3204="사용중")+(실시간콜입력!$O$14:$O$3204="청소중")+(실시간콜입력!$O$14:$O$3204="예약"))),실시간콜입력!$O$14:$O$3204),"빈방") -> 빈방 | K10: {=IFERROR(INDEX(TV설정!$E$4:$E$8,MATCH($C10,TV설정!$D$4:$D$8,0)),60)} -> 60 | L10: =IF($E10="","",IF($E10<TIME(3,0,0),IF(MOD(NOW(),1)<TIME(3,0,0),TODAY()+$E10,TODAY()+1+$E10),TODAY()+$E10))
A11: 103 호실 | B11: =IF(AND($J11="사용중",$F11=0),"종료확인",$J11) -> 빈방 | C11: =IF($J11="빈방","",IFERROR(LOOKUP(2,1/((실시간콜입력!$D$14:$D$3204=$A11)*((실시간콜입력!$O$14:$O$3204="사용중")+(실시간콜입력!$O$14:$O$3204="청소중")+(실시간콜입력!$O$14:$O$3204="예약"))),실시간콜입력!$E$14:$E$3204),"")) | D11: =IF($J11="빈방","",IFERROR(LOOKUP(2,1/((실시간콜입력!$D$14:$D$3204=$A11)*((실시간콜입력!$O$14:$O$3204="사용중")+(실시간콜입력!$O$14:$O$3204="청소중")+(실시간콜입력!$O$14:$O$3204="예약"))),실시간콜입력!$G$14:$G$3204),"")&IF(IFERROR(LOOKUP(2,1/((실시간콜입력!$D$14:$D$3204=$A11)*((실시간콜입력!$O$14:$O$3204="사용중")+(실시간콜입력!$O$14:$O$3204="청소중")+(실시간콜입력!$O$14:$O$3204="예약"))),실시간콜입력!$H$14:$H$3204),"")<>""," / "&IFERROR(LOOKUP(2,1/((실시간콜입력!$D$14:$D$3204=$A11)*((실시간콜입력!$O$14:$O$3204="사용중")+(실시간콜입력!$O$14:$O$3204="청소중")+(실시간콜입력!$O$14:$O$3204="예약"))),실시간콜입력!$H$14:$H$3204),""),"")&IF(IFERROR(LOOKUP(2,1/((실시간콜입력!$D$14:$D$3204=$A11)*((실시간콜입력!$O$14:$O$3204="사용중")+(실시간콜입력!$O$14:$O$3204="청소중")+(실시간콜입력!$O$14:$O$3204="예약"))),실시간콜입력!$I$14:$I$3204),"")<>""," / "&IFERROR(LOOKUP(2,1/((실시간콜입력!$D$14:$D$3204=$A11)*((실시간콜입력!$O$14:$O$3204="사용중")+(실시간콜입력!$O$14:$O$3204="청소중")+(실시간콜입력!$O$14:$O$3204="예약"))),실시간콜입력!$I$14:$I$3204),""),"")) | E11: =IF($J11="빈방","",IFERROR(TIMEVALUE(IFERROR(LOOKUP(2,1/((실시간콜입력!$D$14:$D$3204=$A11)*((실시간콜입력!$O$14:$O$3204="사용중")+(실시간콜입력!$O$14:$O$3204="청소중")+(실시간콜입력!$O$14:$O$3204="예약"))),실시간콜입력!$C$14:$C$3204),"")),IFERROR(LOOKUP(2,1/((실시간콜입력!$D$14:$D$3204=$A11)*((실시간콜입력!$O$14:$O$3204="사용중")+(실시간콜입력!$O$14:$O$3204="청소중")+(실시간콜입력!$O$14:$O$3204="예약"))),실시간콜입력!$C$14:$C$3204),""))) | F11: =IF($J11<>"사용중","",MAX(0,ROUND((($L11+$K11/1440)-NOW())*1440,0))) | G11: =IF($J11="사용중",$E11+$K11/1440,"") | H11: =IF($B11="빈방","입실 가능",IF($B11="청소중","청소 진행",IF($B11="예약","예약 대기",IF($B11="종료확인","종료 확인 필요",$F11&"분 남음")))) -> 입실 가능 | J11: =IFERROR(LOOKUP(2,1/((실시간콜입력!$D$14:$D$3204=$A11)*((실시간콜입력!$O$14:$O$3204="사용중")+(실시간콜입력!$O$14:$O$3204="청소중")+(실시간콜입력!$O$14:$O$3204="예약"))),실시간콜입력!$O$14:$O$3204),"빈방") -> 빈방 | K11: {=IFERROR(INDEX(TV설정!$E$4:$E$8,MATCH($C11,TV설정!$D$4:$D$8,0)),60)} -> 60 | L11: =IF($E11="","",IF($E11<TIME(3,0,0),IF(MOD(NOW(),1)<TIME(3,0,0),TODAY()+$E11,TODAY()+1+$E11),TODAY()+$E11))
A12: 201 호실 | B12: =IF(AND($J12="사용중",$F12=0),"종료확인",$J12) -> 빈방 | C12: =IF($J12="빈방","",IFERROR(LOOKUP(2,1/((실시간콜입력!$D$14:$D$3204=$A12)*((실시간콜입력!$O$14:$O$3204="사용중")+(실시간콜입력!$O$14:$O$3204="청소중")+(실시간콜입력!$O$14:$O$3204="예약"))),실시간콜입력!$E$14:$E$3204),"")) | D12: =IF($J12="빈방","",IFERROR(LOOKUP(2,1/((실시간콜입력!$D$14:$D$3204=$A12)*((실시간콜입력!$O$14:$O$3204="사용중")+(실시간콜입력!$O$14:$O$3204="청소중")+(실시간콜입력!$O$14:$O$3204="예약"))),실시간콜입력!$G$14:$G$3204),"")&IF(IFERROR(LOOKUP(2,1/((실시간콜입력!$D$14:$D$3204=$A12)*((실시간콜입력!$O$14:$O$3204="사용중")+(실시간콜입력!$O$14:$O$3204="청소중")+(실시간콜입력!$O$14:$O$3204="예약"))),실시간콜입력!$H$14:$H$3204),"")<>""," / "&IFERROR(LOOKUP(2,1/((실시간콜입력!$D$14:$D$3204=$A12)*((실시간콜입력!$O$14:$O$3204="사용중")+(실시간콜입력!$O$14:$O$3204="청소중")+(실시간콜입력!$O$14:$O$3204="예약"))),실시간콜입력!$H$14:$H$3204),""),"")&IF(IFERROR(LOOKUP(2,1/((실시간콜입력!$D$14:$D$3204=$A12)*((실시간콜입력!$O$14:$O$3204="사용중")+(실시간콜입력!$O$14:$O$3204="청소중")+(실시간콜입력!$O$14:$O$3204="예약"))),실시간콜입력!$I$14:$I$3204),"")<>""," / "&IFERROR(LOOKUP(2,1/((실시간콜입력!$D$14:$D$3204=$A12)*((실시간콜입력!$O$14:$O$3204="사용중")+(실시간콜입력!$O$14:$O$3204="청소중")+(실시간콜입력!$O$14:$O$3204="예약"))),실시간콜입력!$I$14:$I$3204),""),"")) | E12: =IF($J12="빈방","",IFERROR(TIMEVALUE(IFERROR(LOOKUP(2,1/((실시간콜입력!$D$14:$D$3204=$A12)*((실시간콜입력!$O$14:$O$3204="사용중")+(실시간콜입력!$O$14:$O$3204="청소중")+(실시간콜입력!$O$14:$O$3204="예약"))),실시간콜입력!$C$14:$C$3204),"")),IFERROR(LOOKUP(2,1/((실시간콜입력!$D$14:$D$3204=$A12)*((실시간콜입력!$O$14:$O$3204="사용중")+(실시간콜입력!$O$14:$O$3204="청소중")+(실시간콜입력!$O$14:$O$3204="예약"))),실시간콜입력!$C$14:$C$3204),""))) | F12: =IF($J12<>"사용중","",MAX(0,ROUND((($L12+$K12/1440)-NOW())*1440,0))) | G12: =IF($J12="사용중",$E12+$K12/1440,"") | H12: =IF($B12="빈방","입실 가능",IF($B12="청소중","청소 진행",IF($B12="예약","예약 대기",IF($B12="종료확인","종료 확인 필요",$F12&"분 남음")))) -> 입실 가능 | J12: =IFERROR(LOOKUP(2,1/((실시간콜입력!$D$14:$D$3204=$A12)*((실시간콜입력!$O$14:$O$3204="사용중")+(실시간콜입력!$O$14:$O$3204="청소중")+(실시간콜입력!$O$14:$O$3204="예약"))),실시간콜입력!$O$14:$O$3204),"빈방") -> 빈방 | K12: {=IFERROR(INDEX(TV설정!$E$4:$E$8,MATCH($C12,TV설정!$D$4:$D$8,0)),60)} -> 60 | L12: =IF($E12="","",IF($E12<TIME(3,0,0),IF(MOD(NOW(),1)<TIME(3,0,0),TODAY()+$E12,TODAY()+1+$E12),TODAY()+$E12))
A13: 202 호실 | B13: =IF(AND($J13="사용중",$F13=0),"종료확인",$J13) -> 빈방 | C13: =IF($J13="빈방","",IFERROR(LOOKUP(2,1/((실시간콜입력!$D$14:$D$3204=$A13)*((실시간콜입력!$O$14:$O$3204="사용중")+(실시간콜입력!$O$14:$O$3204="청소중")+(실시간콜입력!$O$14:$O$3204="예약"))),실시간콜입력!$E$14:$E$3204),"")) | D13: =IF($J13="빈방","",IFERROR(LOOKUP(2,1/((실시간콜입력!$D$14:$D$3204=$A13)*((실시간콜입력!$O$14:$O$3204="사용중")+(실시간콜입력!$O$14:$O$3204="청소중")+(실시간콜입력!$O$14:$O$3204="예약"))),실시간콜입력!$G$14:$G$3204),"")&IF(IFERROR(LOOKUP(2,1/((실시간콜입력!$D$14:$D$3204=$A13)*((실시간콜입력!$O$14:$O$3204="사용중")+(실시간콜입력!$O$14:$O$3204="청소중")+(실시간콜입력!$O$14:$O$3204="예약"))),실시간콜입력!$H$14:$H$3204),"")<>""," / "&IFERROR(LOOKUP(2,1/((실시간콜입력!$D$14:$D$3204=$A13)*((실시간콜입력!$O$14:$O$3204="사용중")+(실시간콜입력!$O$14:$O$3204="청소중")+(실시간콜입력!$O$14:$O$3204="예약"))),실시간콜입력!$H$14:$H$3204),""),"")&IF(IFERROR(LOOKUP(2,1/((실시간콜입력!$D$14:$D$3204=$A13)*((실시간콜입력!$O$14:$O$3204="사용중")+(실시간콜입력!$O$14:$O$3204="청소중")+(실시간콜입력!$O$14:$O$3204="예약"))),실시간콜입력!$I$14:$I$3204),"")<>""," / "&IFERROR(LOOKUP(2,1/((실시간콜입력!$D$14:$D$3204=$A13)*((실시간콜입력!$O$14:$O$3204="사용중")+(실시간콜입력!$O$14:$O$3204="청소중")+(실시간콜입력!$O$14:$O$3204="예약"))),실시간콜입력!$I$14:$I$3204),""),"")) | E13: =IF($J13="빈방","",IFERROR(TIMEVALUE(IFERROR(LOOKUP(2,1/((실시간콜입력!$D$14:$D$3204=$A13)*((실시간콜입력!$O$14:$O$3204="사용중")+(실시간콜입력!$O$14:$O$3204="청소중")+(실시간콜입력!$O$14:$O$3204="예약"))),실시간콜입력!$C$14:$C$3204),"")),IFERROR(LOOKUP(2,1/((실시간콜입력!$D$14:$D$3204=$A13)*((실시간콜입력!$O$14:$O$3204="사용중")+(실시간콜입력!$O$14:$O$3204="청소중")+(실시간콜입력!$O$14:$O$3204="예약"))),실시간콜입력!$C$14:$C$3204),""))) | F13: =IF($J13<>"사용중","",MAX(0,ROUND((($L13+$K13/1440)-NOW())*1440,0))) | G13: =IF($J13="사용중",$E13+$K13/1440,"") | H13: =IF($B13="빈방","입실 가능",IF($B13="청소중","청소 진행",IF($B13="예약","예약 대기",IF($B13="종료확인","종료 확인 필요",$F13&"분 남음")))) -> 입실 가능 | J13: =IFERROR(LOOKUP(2,1/((실시간콜입력!$D$14:$D$3204=$A13)*((실시간콜입력!$O$14:$O$3204="사용중")+(실시간콜입력!$O$14:$O$3204="청소중")+(실시간콜입력!$O$14:$O$3204="예약"))),실시간콜입력!$O$14:$O$3204),"빈방") -> 빈방 | K13: {=IFERROR(INDEX(TV설정!$E$4:$E$8,MATCH($C13,TV설정!$D$4:$D$8,0)),60)} -> 60 | L13: =IF($E13="","",IF($E13<TIME(3,0,0),IF(MOD(NOW(),1)<TIME(3,0,0),TODAY()+$E13,TODAY()+1+$E13),TODAY()+$E13))
A14: 203 호실 | B14: =IF(AND($J14="사용중",$F14=0),"종료확인",$J14) -> 빈방 | C14: =IF($J14="빈방","",IFERROR(LOOKUP(2,1/((실시간콜입력!$D$14:$D$3204=$A14)*((실시간콜입력!$O$14:$O$3204="사용중")+(실시간콜입력!$O$14:$O$3204="청소중")+(실시간콜입력!$O$14:$O$3204="예약"))),실시간콜입력!$E$14:$E$3204),"")) | D14: =IF($J14="빈방","",IFERROR(LOOKUP(2,1/((실시간콜입력!$D$14:$D$3204=$A14)*((실시간콜입력!$O$14:$O$3204="사용중")+(실시간콜입력!$O$14:$O$3204="청소중")+(실시간콜입력!$O$14:$O$3204="예약"))),실시간콜입력!$G$14:$G$3204),"")&IF(IFERROR(LOOKUP(2,1/((실시간콜입력!$D$14:$D$3204=$A14)*((실시간콜입력!$O$14:$O$3204="사용중")+(실시간콜입력!$O$14:$O$3204="청소중")+(실시간콜입력!$O$14:$O$3204="예약"))),실시간콜입력!$H$14:$H$3204),"")<>""," / "&IFERROR(LOOKUP(2,1/((실시간콜입력!$D$14:$D$3204=$A14)*((실시간콜입력!$O$14:$O$3204="사용중")+(실시간콜입력!$O$14:$O$3204="청소중")+(실시간콜입력!$O$14:$O$3204="예약"))),실시간콜입력!$H$14:$H$3204),""),"")&IF(IFERROR(LOOKUP(2,1/((실시간콜입력!$D$14:$D$3204=$A14)*((실시간콜입력!$O$14:$O$3204="사용중")+(실시간콜입력!$O$14:$O$3204="청소중")+(실시간콜입력!$O$14:$O$3204="예약"))),실시간콜입력!$I$14:$I$3204),"")<>""," / "&IFERROR(LOOKUP(2,1/((실시간콜입력!$D$14:$D$3204=$A14)*((실시간콜입력!$O$14:$O$3204="사용중")+(실시간콜입력!$O$14:$O$3204="청소중")+(실시간콜입력!$O$14:$O$3204="예약"))),실시간콜입력!$I$14:$I$3204),""),"")) | E14: =IF($J14="빈방","",IFERROR(TIMEVALUE(IFERROR(LOOKUP(2,1/((실시간콜입력!$D$14:$D$3204=$A14)*((실시간콜입력!$O$14:$O$3204="사용중")+(실시간콜입력!$O$14:$O$3204="청소중")+(실시간콜입력!$O$14:$O$3204="예약"))),실시간콜입력!$C$14:$C$3204),"")),IFERROR(LOOKUP(2,1/((실시간콜입력!$D$14:$D$3204=$A14)*((실시간콜입력!$O$14:$O$3204="사용중")+(실시간콜입력!$O$14:$O$3204="청소중")+(실시간콜입력!$O$14:$O$3204="예약"))),실시간콜입력!$C$14:$C$3204),""))) | F14: =IF($J14<>"사용중","",MAX(0,ROUND((($L14+$K14/1440)-NOW())*1440,0))) | G14: =IF($J14="사용중",$E14+$K14/1440,"") | H14: =IF($B14="빈방","입실 가능",IF($B14="청소중","청소 진행",IF($B14="예약","예약 대기",IF($B14="종료확인","종료 확인 필요",$F14&"분 남음")))) -> 입실 가능 | J14: =IFERROR(LOOKUP(2,1/((실시간콜입력!$D$14:$D$3204=$A14)*((실시간콜입력!$O$14:$O$3204="사용중")+(실시간콜입력!$O$14:$O$3204="청소중")+(실시간콜입력!$O$14:$O$3204="예약"))),실시간콜입력!$O$14:$O$3204),"빈방") -> 빈방 | K14: {=IFERROR(INDEX(TV설정!$E$4:$E$8,MATCH($C14,TV설정!$D$4:$D$8,0)),60)} -> 60 | L14: =IF($E14="","",IF($E14<TIME(3,0,0),IF(MOD(NOW(),1)<TIME(3,0,0),TODAY()+$E14,TODAY()+1+$E14),TODAY()+$E14))
A15: 301 호실 | B15: =IF(AND($J15="사용중",$F15=0),"종료확인",$J15) -> 빈방 | C15: =IF($J15="빈방","",IFERROR(LOOKUP(2,1/((실시간콜입력!$D$14:$D$3204=$A15)*((실시간콜입력!$O$14:$O$3204="사용중")+(실시간콜입력!$O$14:$O$3204="청소중")+(실시간콜입력!$O$14:$O$3204="예약"))),실시간콜입력!$E$14:$E$3204),"")) | D15: =IF($J15="빈방","",IFERROR(LOOKUP(2,1/((실시간콜입력!$D$14:$D$3204=$A15)*((실시간콜입력!$O$14:$O$3204="사용중")+(실시간콜입력!$O$14:$O$3204="청소중")+(실시간콜입력!$O$14:$O$3204="예약"))),실시간콜입력!$G$14:$G$3204),"")&IF(IFERROR(LOOKUP(2,1/((실시간콜입력!$D$14:$D$3204=$A15)*((실시간콜입력!$O$14:$O$3204="사용중")+(실시간콜입력!$O$14:$O$3204="청소중")+(실시간콜입력!$O$14:$O$3204="예약"))),실시간콜입력!$H$14:$H$3204),"")<>""," / "&IFERROR(LOOKUP(2,1/((실시간콜입력!$D$14:$D$3204=$A15)*((실시간콜입력!$O$14:$O$3204="사용중")+(실시간콜입력!$O$14:$O$3204="청소중")+(실시간콜입력!$O$14:$O$3204="예약"))),실시간콜입력!$H$14:$H$3204),""),"")&IF(IFERROR(LOOKUP(2,1/((실시간콜입력!$D$14:$D$3204=$A15)*((실시간콜입력!$O$14:$O$3204="사용중")+(실시간콜입력!$O$14:$O$3204="청소중")+(실시간콜입력!$O$14:$O$3204="예약"))),실시간콜입력!$I$14:$I$3204),"")<>""," / "&IFERROR(LOOKUP(2,1/((실시간콜입력!$D$14:$D$3204=$A15)*((실시간콜입력!$O$14:$O$3204="사용중")+(실시간콜입력!$O$14:$O$3204="청소중")+(실시간콜입력!$O$14:$O$3204="예약"))),실시간콜입력!$I$14:$I$3204),""),"")) | E15: =IF($J15="빈방","",IFERROR(TIMEVALUE(IFERROR(LOOKUP(2,1/((실시간콜입력!$D$14:$D$3204=$A15)*((실시간콜입력!$O$14:$O$3204="사용중")+(실시간콜입력!$O$14:$O$3204="청소중")+(실시간콜입력!$O$14:$O$3204="예약"))),실시간콜입력!$C$14:$C$3204),"")),IFERROR(LOOKUP(2,1/((실시간콜입력!$D$14:$D$3204=$A15)*((실시간콜입력!$O$14:$O$3204="사용중")+(실시간콜입력!$O$14:$O$3204="청소중")+(실시간콜입력!$O$14:$O$3204="예약"))),실시간콜입력!$C$14:$C$3204),""))) | F15: =IF($J15<>"사용중","",MAX(0,ROUND((($L15+$K15/1440)-NOW())*1440,0))) | G15: =IF($J15="사용중",$E15+$K15/1440,"") | H15: =IF($B15="빈방","입실 가능",IF($B15="청소중","청소 진행",IF($B15="예약","예약 대기",IF($B15="종료확인","종료 확인 필요",$F15&"분 남음")))) -> 입실 가능 | J15: =IFERROR(LOOKUP(2,1/((실시간콜입력!$D$14:$D$3204=$A15)*((실시간콜입력!$O$14:$O$3204="사용중")+(실시간콜입력!$O$14:$O$3204="청소중")+(실시간콜입력!$O$14:$O$3204="예약"))),실시간콜입력!$O$14:$O$3204),"빈방") -> 빈방 | K15: {=IFERROR(INDEX(TV설정!$E$4:$E$8,MATCH($C15,TV설정!$D$4:$D$8,0)),60)} -> 60 | L15: =IF($E15="","",IF($E15<TIME(3,0,0),IF(MOD(NOW(),1)<TIME(3,0,0),TODAY()+$E15,TODAY()+1+$E15),TODAY()+$E15))
A16: 302 호실 | B16: =IF(AND($J16="사용중",$F16=0),"종료확인",$J16) -> 빈방 | C16: =IF($J16="빈방","",IFERROR(LOOKUP(2,1/((실시간콜입력!$D$14:$D$3204=$A16)*((실시간콜입력!$O$14:$O$3204="사용중")+(실시간콜입력!$O$14:$O$3204="청소중")+(실시간콜입력!$O$14:$O$3204="예약"))),실시간콜입력!$E$14:$E$3204),"")) | D16: =IF($J16="빈방","",IFERROR(LOOKUP(2,1/((실시간콜입력!$D$14:$D$3204=$A16)*((실시간콜입력!$O$14:$O$3204="사용중")+(실시간콜입력!$O$14:$O$3204="청소중")+(실시간콜입력!$O$14:$O$3204="예약"))),실시간콜입력!$G$14:$G$3204),"")&IF(IFERROR(LOOKUP(2,1/((실시간콜입력!$D$14:$D$3204=$A16)*((실시간콜입력!$O$14:$O$3204="사용중")+(실시간콜입력!$O$14:$O$3204="청소중")+(실시간콜입력!$O$14:$O$3204="예약"))),실시간콜입력!$H$14:$H$3204),"")<>""," / "&IFERROR(LOOKUP(2,1/((실시간콜입력!$D$14:$D$3204=$A16)*((실시간콜입력!$O$14:$O$3204="사용중")+(실시간콜입력!$O$14:$O$3204="청소중")+(실시간콜입력!$O$14:$O$3204="예약"))),실시간콜입력!$H$14:$H$3204),""),"")&IF(IFERROR(LOOKUP(2,1/((실시간콜입력!$D$14:$D$3204=$A16)*((실시간콜입력!$O$14:$O$3204="사용중")+(실시간콜입력!$O$14:$O$3204="청소중")+(실시간콜입력!$O$14:$O$3204="예약"))),실시간콜입력!$I$14:$I$3204),"")<>""," / "&IFERROR(LOOKUP(2,1/((실시간콜입력!$D$14:$D$3204=$A16)*((실시간콜입력!$O$14:$O$3204="사용중")+(실시간콜입력!$O$14:$O$3204="청소중")+(실시간콜입력!$O$14:$O$3204="예약"))),실시간콜입력!$I$14:$I$3204),""),"")) | E16: =IF($J16="빈방","",IFERROR(TIMEVALUE(IFERROR(LOOKUP(2,1/((실시간콜입력!$D$14:$D$3204=$A16)*((실시간콜입력!$O$14:$O$3204="사용중")+(실시간콜입력!$O$14:$O$3204="청소중")+(실시간콜입력!$O$14:$O$3204="예약"))),실시간콜입력!$C$14:$C$3204),"")),IFERROR(LOOKUP(2,1/((실시간콜입력!$D$14:$D$3204=$A16)*((실시간콜입력!$O$14:$O$3204="사용중")+(실시간콜입력!$O$14:$O$3204="청소중")+(실시간콜입력!$O$14:$O$3204="예약"))),실시간콜입력!$C$14:$C$3204),""))) | F16: =IF($J16<>"사용중","",MAX(0,ROUND((($L16+$K16/1440)-NOW())*1440,0))) | G16: =IF($J16="사용중",$E16+$K16/1440,"") | H16: =IF($B16="빈방","입실 가능",IF($B16="청소중","청소 진행",IF($B16="예약","예약 대기",IF($B16="종료확인","종료 확인 필요",$F16&"분 남음")))) -> 입실 가능 | J16: =IFERROR(LOOKUP(2,1/((실시간콜입력!$D$14:$D$3204=$A16)*((실시간콜입력!$O$14:$O$3204="사용중")+(실시간콜입력!$O$14:$O$3204="청소중")+(실시간콜입력!$O$14:$O$3204="예약"))),실시간콜입력!$O$14:$O$3204),"빈방") -> 빈방 | K16: {=IFERROR(INDEX(TV설정!$E$4:$E$8,MATCH($C16,TV설정!$D$4:$D$8,0)),60)} -> 60 | L16: =IF($E16="","",IF($E16<TIME(3,0,0),IF(MOD(NOW(),1)<TIME(3,0,0),TODAY()+$E16,TODAY()+1+$E16),TODAY()+$E16))
A17: 303 호실 | B17: =IF(AND($J17="사용중",$F17=0),"종료확인",$J17) -> 빈방 | C17: =IF($J17="빈방","",IFERROR(LOOKUP(2,1/((실시간콜입력!$D$14:$D$3204=$A17)*((실시간콜입력!$O$14:$O$3204="사용중")+(실시간콜입력!$O$14:$O$3204="청소중")+(실시간콜입력!$O$14:$O$3204="예약"))),실시간콜입력!$E$14:$E$3204),"")) | D17: =IF($J17="빈방","",IFERROR(LOOKUP(2,1/((실시간콜입력!$D$14:$D$3204=$A17)*((실시간콜입력!$O$14:$O$3204="사용중")+(실시간콜입력!$O$14:$O$3204="청소중")+(실시간콜입력!$O$14:$O$3204="예약"))),실시간콜입력!$G$14:$G$3204),"")&IF(IFERROR(LOOKUP(2,1/((실시간콜입력!$D$14:$D$3204=$A17)*((실시간콜입력!$O$14:$O$3204="사용중")+(실시간콜입력!$O$14:$O$3204="청소중")+(실시간콜입력!$O$14:$O$3204="예약"))),실시간콜입력!$H$14:$H$3204),"")<>""," / "&IFERROR(LOOKUP(2,1/((실시간콜입력!$D$14:$D$3204=$A17)*((실시간콜입력!$O$14:$O$3204="사용중")+(실시간콜입력!$O$14:$O$3204="청소중")+(실시간콜입력!$O$14:$O$3204="예약"))),실시간콜입력!$H$14:$H$3204),""),"")&IF(IFERROR(LOOKUP(2,1/((실시간콜입력!$D$14:$D$3204=$A17)*((실시간콜입력!$O$14:$O$3204="사용중")+(실시간콜입력!$O$14:$O$3204="청소중")+(실시간콜입력!$O$14:$O$3204="예약"))),실시간콜입력!$I$14:$I$3204),"")<>""," / "&IFERROR(LOOKUP(2,1/((실시간콜입력!$D$14:$D$3204=$A17)*((실시간콜입력!$O$14:$O$3204="사용중")+(실시간콜입력!$O$14:$O$3204="청소중")+(실시간콜입력!$O$14:$O$3204="예약"))),실시간콜입력!$I$14:$I$3204),""),"")) | E17: =IF($J17="빈방","",IFERROR(TIMEVALUE(IFERROR(LOOKUP(2,1/((실시간콜입력!$D$14:$D$3204=$A17)*((실시간콜입력!$O$14:$O$3204="사용중")+(실시간콜입력!$O$14:$O$3204="청소중")+(실시간콜입력!$O$14:$O$3204="예약"))),실시간콜입력!$C$14:$C$3204),"")),IFERROR(LOOKUP(2,1/((실시간콜입력!$D$14:$D$3204=$A17)*((실시간콜입력!$O$14:$O$3204="사용중")+(실시간콜입력!$O$14:$O$3204="청소중")+(실시간콜입력!$O$14:$O$3204="예약"))),실시간콜입력!$C$14:$C$3204),""))) | F17: =IF($J17<>"사용중","",MAX(0,ROUND((($L17+$K17/1440)-NOW())*1440,0))) | G17: =IF($J17="사용중",$E17+$K17/1440,"") | H17: =IF($B17="빈방","입실 가능",IF($B17="청소중","청소 진행",IF($B17="예약","예약 대기",IF($B17="종료확인","종료 확인 필요",$F17&"분 남음")))) -> 입실 가능 | J17: =IFERROR(LOOKUP(2,1/((실시간콜입력!$D$14:$D$3204=$A17)*((실시간콜입력!$O$14:$O$3204="사용중")+(실시간콜입력!$O$14:$O$3204="청소중")+(실시간콜입력!$O$14:$O$3204="예약"))),실시간콜입력!$O$14:$O$3204),"빈방") -> 빈방 | K17: {=IFERROR(INDEX(TV설정!$E$4:$E$8,MATCH($C17,TV설정!$D$4:$D$8,0)),60)} -> 60 | L17: =IF($E17="","",IF($E17<TIME(3,0,0),IF(MOD(NOW(),1)<TIME(3,0,0),TODAY()+$E17,TODAY()+1+$E17),TODAY()+$E17))
A18: 401 호실 | B18: =IF(AND($J18="사용중",$F18=0),"종료확인",$J18) -> 빈방 | C18: =IF($J18="빈방","",IFERROR(LOOKUP(2,1/((실시간콜입력!$D$14:$D$3204=$A18)*((실시간콜입력!$O$14:$O$3204="사용중")+(실시간콜입력!$O$14:$O$3204="청소중")+(실시간콜입력!$O$14:$O$3204="예약"))),실시간콜입력!$E$14:$E$3204),"")) | D18: =IF($J18="빈방","",IFERROR(LOOKUP(2,1/((실시간콜입력!$D$14:$D$3204=$A18)*((실시간콜입력!$O$14:$O$3204="사용중")+(실시간콜입력!$O$14:$O$3204="청소중")+(실시간콜입력!$O$14:$O$3204="예약"))),실시간콜입력!$G$14:$G$3204),"")&IF(IFERROR(LOOKUP(2,1/((실시간콜입력!$D$14:$D$3204=$A18)*((실시간콜입력!$O$14:$O$3204="사용중")+(실시간콜입력!$O$14:$O$3204="청소중")+(실시간콜입력!$O$14:$O$3204="예약"))),실시간콜입력!$H$14:$H$3204),"")<>""," / "&IFERROR(LOOKUP(2,1/((실시간콜입력!$D$14:$D$3204=$A18)*((실시간콜입력!$O$14:$O$3204="사용중")+(실시간콜입력!$O$14:$O$3204="청소중")+(실시간콜입력!$O$14:$O$3204="예약"))),실시간콜입력!$H$14:$H$3204),""),"")&IF(IFERROR(LOOKUP(2,1/((실시간콜입력!$D$14:$D$3204=$A18)*((실시간콜입력!$O$14:$O$3204="사용중")+(실시간콜입력!$O$14:$O$3204="청소중")+(실시간콜입력!$O$14:$O$3204="예약"))),실시간콜입력!$I$14:$I$3204),"")<>""," / "&IFERROR(LOOKUP(2,1/((실시간콜입력!$D$14:$D$3204=$A18)*((실시간콜입력!$O$14:$O$3204="사용중")+(실시간콜입력!$O$14:$O$3204="청소중")+(실시간콜입력!$O$14:$O$3204="예약"))),실시간콜입력!$I$14:$I$3204),""),"")) | E18: =IF($J18="빈방","",IFERROR(TIMEVALUE(IFERROR(LOOKUP(2,1/((실시간콜입력!$D$14:$D$3204=$A18)*((실시간콜입력!$O$14:$O$3204="사용중")+(실시간콜입력!$O$14:$O$3204="청소중")+(실시간콜입력!$O$14:$O$3204="예약"))),실시간콜입력!$C$14:$C$3204),"")),IFERROR(LOOKUP(2,1/((실시간콜입력!$D$14:$D$3204=$A18)*((실시간콜입력!$O$14:$O$3204="사용중")+(실시간콜입력!$O$14:$O$3204="청소중")+(실시간콜입력!$O$14:$O$3204="예약"))),실시간콜입력!$C$14:$C$3204),""))) | F18: =IF($J18<>"사용중","",MAX(0,ROUND((($L18+$K18/1440)-NOW())*1440,0))) | G18: =IF($J18="사용중",$E18+$K18/1440,"") | H18: =IF($B18="빈방","입실 가능",IF($B18="청소중","청소 진행",IF($B18="예약","예약 대기",IF($B18="종료확인","종료 확인 필요",$F18&"분 남음")))) -> 입실 가능 | J18: =IFERROR(LOOKUP(2,1/((실시간콜입력!$D$14:$D$3204=$A18)*((실시간콜입력!$O$14:$O$3204="사용중")+(실시간콜입력!$O$14:$O$3204="청소중")+(실시간콜입력!$O$14:$O$3204="예약"))),실시간콜입력!$O$14:$O$3204),"빈방") -> 빈방 | K18: {=IFERROR(INDEX(TV설정!$E$4:$E$8,MATCH($C18,TV설정!$D$4:$D$8,0)),60)} -> 60 | L18: =IF($E18="","",IF($E18<TIME(3,0,0),IF(MOD(NOW(),1)<TIME(3,0,0),TODAY()+$E18,TODAY()+1+$E18),TODAY()+$E18))
A19: 402 호실 | B19: =IF(AND($J19="사용중",$F19=0),"종료확인",$J19) -> 빈방 | C19: =IF($J19="빈방","",IFERROR(LOOKUP(2,1/((실시간콜입력!$D$14:$D$3204=$A19)*((실시간콜입력!$O$14:$O$3204="사용중")+(실시간콜입력!$O$14:$O$3204="청소중")+(실시간콜입력!$O$14:$O$3204="예약"))),실시간콜입력!$E$14:$E$3204),"")) | D19: =IF($J19="빈방","",IFERROR(LOOKUP(2,1/((실시간콜입력!$D$14:$D$3204=$A19)*((실시간콜입력!$O$14:$O$3204="사용중")+(실시간콜입력!$O$14:$O$3204="청소중")+(실시간콜입력!$O$14:$O$3204="예약"))),실시간콜입력!$G$14:$G$3204),"")&IF(IFERROR(LOOKUP(2,1/((실시간콜입력!$D$14:$D$3204=$A19)*((실시간콜입력!$O$14:$O$3204="사용중")+(실시간콜입력!$O$14:$O$3204="청소중")+(실시간콜입력!$O$14:$O$3204="예약"))),실시간콜입력!$H$14:$H$3204),"")<>""," / "&IFERROR(LOOKUP(2,1/((실시간콜입력!$D$14:$D$3204=$A19)*((실시간콜입력!$O$14:$O$3204="사용중")+(실시간콜입력!$O$14:$O$3204="청소중")+(실시간콜입력!$O$14:$O$3204="예약"))),실시간콜입력!$H$14:$H$3204),""),"")&IF(IFERROR(LOOKUP(2,1/((실시간콜입력!$D$14:$D$3204=$A19)*((실시간콜입력!$O$14:$O$3204="사용중")+(실시간콜입력!$O$14:$O$3204="청소중")+(실시간콜입력!$O$14:$O$3204="예약"))),실시간콜입력!$I$14:$I$3204),"")<>""," / "&IFERROR(LOOKUP(2,1/((실시간콜입력!$D$14:$D$3204=$A19)*((실시간콜입력!$O$14:$O$3204="사용중")+(실시간콜입력!$O$14:$O$3204="청소중")+(실시간콜입력!$O$14:$O$3204="예약"))),실시간콜입력!$I$14:$I$3204),""),"")) | E19: =IF($J19="빈방","",IFERROR(TIMEVALUE(IFERROR(LOOKUP(2,1/((실시간콜입력!$D$14:$D$3204=$A19)*((실시간콜입력!$O$14:$O$3204="사용중")+(실시간콜입력!$O$14:$O$3204="청소중")+(실시간콜입력!$O$14:$O$3204="예약"))),실시간콜입력!$C$14:$C$3204),"")),IFERROR(LOOKUP(2,1/((실시간콜입력!$D$14:$D$3204=$A19)*((실시간콜입력!$O$14:$O$3204="사용중")+(실시간콜입력!$O$14:$O$3204="청소중")+(실시간콜입력!$O$14:$O$3204="예약"))),실시간콜입력!$C$14:$C$3204),""))) | F19: =IF($J19<>"사용중","",MAX(0,ROUND((($L19+$K19/1440)-NOW())*1440,0))) | G19: =IF($J19="사용중",$E19+$K19/1440,"") | H19: =IF($B19="빈방","입실 가능",IF($B19="청소중","청소 진행",IF($B19="예약","예약 대기",IF($B19="종료확인","종료 확인 필요",$F19&"분 남음")))) -> 입실 가능 | J19: =IFERROR(LOOKUP(2,1/((실시간콜입력!$D$14:$D$3204=$A19)*((실시간콜입력!$O$14:$O$3204="사용중")+(실시간콜입력!$O$14:$O$3204="청소중")+(실시간콜입력!$O$14:$O$3204="예약"))),실시간콜입력!$O$14:$O$3204),"빈방") -> 빈방 | K19: {=IFERROR(INDEX(TV설정!$E$4:$E$8,MATCH($C19,TV설정!$D$4:$D$8,0)),60)} -> 60 | L19: =IF($E19="","",IF($E19<TIME(3,0,0),IF(MOD(NOW(),1)<TIME(3,0,0),TODAY()+$E19,TODAY()+1+$E19),TODAY()+$E19))
A22: 사용 순서: 실시간콜입력에서 시간/방번호/코스/마사지사1/예약상태를 선택하면 TV현황판과 웨이터리스트가 자동 반영됩니다.
A23: 상태 흐름: 예약 → 사용중 → 청소중 → 방문완료. 방문완료/취소/노쇼는 TV에서 자동 제외되어 빈방처럼 표시됩니다.
A24: 남은시간은 사용중 상태에서만 표시됩니다. 시간이 0분이 되면 종료확인으로 표시됩니다.
A25: 구글스프레드시트로 옮긴 뒤 TV현황판 또는 웨이터리스트 시트만 전체화면으로 띄우면 됩니다.

Sheet TV현황판
A1: GANGNAM SPA LIVE ROOM BOARD
A2: 카운터 TV 전체화면용 · 웨이터리스트와 자동 연동
A4: 사용중 | B4: 예약 | C4: 청소중 | D4: 종료확인 | E4: 빈방 | F4: 곧 종료
A5: =웨이터리스트!A5 -> 0 | B5: =웨이터리스트!B5 -> 0 | C5: =웨이터리스트!C5 -> 0 | D5: =웨이터리스트!D5 -> 0 | E5: =웨이터리스트!E5 -> 11 | F5: =웨이터리스트!F5 -> 0
A7: =웨이터리스트!$A$18 -> 401 호실 | D7: =웨이터리스트!$A$19 -> 402 호실
A8: =IF(웨이터리스트!$B$18="사용중","사용중",IF(웨이터리스트!$B$18="청소중","청소중",IF(웨이터리스트!$B$18="예약","예약",IF(웨이터리스트!$B$18="종료확인","종료확인","빈방")))) -> 빈방 | D8: =IF(웨이터리스트!$B$19="사용중","사용중",IF(웨이터리스트!$B$19="청소중","청소중",IF(웨이터리스트!$B$19="예약","예약",IF(웨이터리스트!$B$19="종료확인","종료확인","빈방")))) -> 빈방
A9: =IF(웨이터리스트!$F$18="","","⏱ 남은시간 : "&웨이터리스트!$F$18&"분") | D9: =IF(웨이터리스트!$F$19="","","⏱ 남은시간 : "&웨이터리스트!$F$19&"분")
A10: =IF(OR(웨이터리스트!$B$18="사용중",웨이터리스트!$B$18="예약"),웨이터리스트!$C$18,"") | D10: =IF(OR(웨이터리스트!$B$19="사용중",웨이터리스트!$B$19="예약"),웨이터리스트!$C$19,"")
A11: =IF(웨이터리스트!$D$18="","","담당: "&웨이터리스트!$D$18) | D11: =IF(웨이터리스트!$D$19="","","담당: "&웨이터리스트!$D$19)
A13: =웨이터리스트!$A$15 -> 301 호실 | D13: =웨이터리스트!$A$16 -> 302 호실 | G13: =웨이터리스트!$A$17 -> 303 호실
A14: =IF(웨이터리스트!$B$15="사용중","사용중",IF(웨이터리스트!$B$15="청소중","청소중",IF(웨이터리스트!$B$15="예약","예약",IF(웨이터리스트!$B$15="종료확인","종료확인","빈방")))) -> 빈방 | D14: =IF(웨이터리스트!$B$16="사용중","사용중",IF(웨이터리스트!$B$16="청소중","청소중",IF(웨이터리스트!$B$16="예약","예약",IF(웨이터리스트!$B$16="종료확인","종료확인","빈방")))) -> 빈방 | G14: =IF(웨이터리스트!$B$17="사용중","사용중",IF(웨이터리스트!$B$17="청소중","청소중",IF(웨이터리스트!$B$17="예약","예약",IF(웨이터리스트!$B$17="종료확인","종료확인","빈방")))) -> 빈방
A15: =IF(웨이터리스트!$F$15="","","⏱ 남은시간 : "&웨이터리스트!$F$15&"분") | D15: =IF(웨이터리스트!$F$16="","","⏱ 남은시간 : "&웨이터리스트!$F$16&"분") | G15: =IF(웨이터리스트!$F$17="","","⏱ 남은시간 : "&웨이터리스트!$F$17&"분")
A16: =IF(OR(웨이터리스트!$B$15="사용중",웨이터리스트!$B$15="예약"),웨이터리스트!$C$15,"") | D16: =IF(OR(웨이터리스트!$B$16="사용중",웨이터리스트!$B$16="예약"),웨이터리스트!$C$16,"") | G16: =IF(OR(웨이터리스트!$B$17="사용중",웨이터리스트!$B$17="예약"),웨이터리스트!$C$17,"")
A17: =IF(웨이터리스트!$D$15="","","담당: "&웨이터리스트!$D$15) | D17: =IF(웨이터리스트!$D$16="","","담당: "&웨이터리스트!$D$16) | G17: =IF(웨이터리스트!$D$17="","","담당: "&웨이터리스트!$D$17)
A19: =웨이터리스트!$A$12 -> 201 호실 | D19: =웨이터리스트!$A$13 -> 202 호실 | G19: =웨이터리스트!$A$14 -> 203 호실
A20: =IF(웨이터리스트!$B$12="사용중","사용중",IF(웨이터리스트!$B$12="청소중","청소중",IF(웨이터리스트!$B$12="예약","예약",IF(웨이터리스트!$B$12="종료확인","종료확인","빈방")))) -> 빈방 | D20: =IF(웨이터리스트!$B$13="사용중","사용중",IF(웨이터리스트!$B$13="청소중","청소중",IF(웨이터리스트!$B$13="예약","예약",IF(웨이터리스트!$B$13="종료확인","종료확인","빈방")))) -> 빈방 | G20: =IF(웨이터리스트!$B$14="사용중","사용중",IF(웨이터리스트!$B$14="청소중","청소중",IF(웨이터리스트!$B$14="예약","예약",IF(웨이터리스트!$B$14="종료확인","종료확인","빈방")))) -> 빈방
A21: =IF(웨이터리스트!$F$12="","","⏱ 남은시간 : "&웨이터리스트!$F$12&"분") | D21: =IF(웨이터리스트!$F$13="","","⏱ 남은시간 : "&웨이터리스트!$F$13&"분") | G21: =IF(웨이터리스트!$F$14="","","⏱ 남은시간 : "&웨이터리스트!$F$14&"분")
A22: =IF(OR(웨이터리스트!$B$12="사용중",웨이터리스트!$B$12="예약"),웨이터리스트!$C$12,"") | D22: =IF(OR(웨이터리스트!$B$13="사용중",웨이터리스트!$B$13="예약"),웨이터리스트!$C$13,"") | G22: =IF(OR(웨이터리스트!$B$14="사용중",웨이터리스트!$B$14="예약"),웨이터리스트!$C$14,"")
A23: =IF(웨이터리스트!$D$12="","","담당: "&웨이터리스트!$D$12) | D23: =IF(웨이터리스트!$D$13="","","담당: "&웨이터리스트!$D$13) | G23: =IF(웨이터리스트!$D$14="","","담당: "&웨이터리스트!$D$14)
A25: =웨이터리스트!$A$9 -> 101 호실 | D25: =웨이터리스트!$A$10 -> 102 호실 | G25: =웨이터리스트!$A$11 -> 103 호실
A26: =IF(웨이터리스트!$B$9="사용중","사용중",IF(웨이터리스트!$B$9="청소중","청소중",IF(웨이터리스트!$B$9="예약","예약",IF(웨이터리스트!$B$9="종료확인","종료확인","빈방")))) -> 빈방 | D26: =IF(웨이터리스트!$B$10="사용중","사용중",IF(웨이터리스트!$B$10="청소중","청소중",IF(웨이터리스트!$B$10="예약","예약",IF(웨이터리스트!$B$10="종료확인","종료확인","빈방")))) -> 빈방 | G26: =IF(웨이터리스트!$B$11="사용중","사용중",IF(웨이터리스트!$B$11="청소중","청소중",IF(웨이터리스트!$B$11="예약","예약",IF(웨이터리스트!$B$11="종료확인","종료확인","빈방")))) -> 빈방
A27: =IF(웨이터리스트!$F$9="","","⏱ 남은시간 : "&웨이터리스트!$F$9&"분") | D27: =IF(웨이터리스트!$F$10="","","⏱ 남은시간 : "&웨이터리스트!$F$10&"분") | G27: =IF(웨이터리스트!$F$11="","","⏱ 남은시간 : "&웨이터리스트!$F$11&"분")
A28: =IF(OR(웨이터리스트!$B$9="사용중",웨이터리스트!$B$9="예약"),웨이터리스트!$C$9,"") | D28: =IF(OR(웨이터리스트!$B$10="사용중",웨이터리스트!$B$10="예약"),웨이터리스트!$C$10,"") | G28: =IF(OR(웨이터리스트!$B$11="사용중",웨이터리스트!$B$11="예약"),웨이터리스트!$C$11,"")
A29: =IF(웨이터리스트!$D$9="","","담당: "&웨이터리스트!$D$9) | D29: =IF(웨이터리스트!$D$10="","","담당: "&웨이터리스트!$D$10) | G29: =IF(웨이터리스트!$D$11="","","담당: "&웨이터리스트!$D$11)
A31: TV 사용: 이 시트를 전체화면으로 띄우면 방 상태·코스·남은시간·담당자를 한눈에 볼 수 있습니다.
A32: 수정은 실시간콜입력 시트에서만 하세요. TV현황판은 보는 용도입니다.

Sheet 운영팀근무인센
A1: 운영팀 근무 / 일일인센 / 월인센
A2: 출근상태는 정상/휴무/지각/조퇴/결근 중 선택. 지각·조퇴·결근은 해당일 일일인센 0원 처리.
A4: 날짜 | B4: 총콜 | C4: 일일개인인센 | D4: 팀장상태 | E4: 팀장인센 | F4: 카운터1상태 | G4: 카운터1인센 | H4: 카운터2상태 | I4: 카운터2인센 | J4: 웨이터1상태 | K4: 웨이터1인센 | L4: 웨이터2상태 | M4: 웨이터2인센
A5: =IF(1<=DAY(DATE(YEAR(설정_코스수당!$K$2),MONTH(설정_코스수당!$K$2)+1,0)),DATE(YEAR(설정_코스수당!$K$2),MONTH(설정_코스수당!$K$2),1),"") -> 46174 | B5: =COUNTIFS(실시간콜입력!$B:$B,A5,실시간콜입력!$O:$O,"방문완료") -> 0 | C5: =IF(B5>=설정_코스수당!$A$71,설정_코스수당!$B$71,IF(B5>=설정_코스수당!$A$70,설정_코스수당!$B$70,IF(B5>=설정_코스수당!$A$69,설정_코스수당!$B$69,0))) -> 0 | D5: 정상 | E5: =IF(D5="정상",$C5,0) -> 0 | F5: 정상 | G5: =IF(F5="정상",$C5,0) -> 0 | H5: 정상 | I5: =IF(H5="정상",$C5,0) -> 0 | J5: 정상 | K5: =IF(J5="정상",$C5,0) -> 0 | L5: 정상 | M5: =IF(L5="정상",$C5,0) -> 0
A6: =IF(2<=DAY(DATE(YEAR(설정_코스수당!$K$2),MONTH(설정_코스수당!$K$2)+1,0)),DATE(YEAR(설정_코스수당!$K$2),MONTH(설정_코스수당!$K$2),2),"") -> 46175 | B6: =COUNTIFS(실시간콜입력!$B:$B,A6,실시간콜입력!$O:$O,"방문완료") -> 0 | C6: =IF(B6>=설정_코스수당!$A$71,설정_코스수당!$B$71,IF(B6>=설정_코스수당!$A$70,설정_코스수당!$B$70,IF(B6>=설정_코스수당!$A$69,설정_코스수당!$B$69,0))) -> 0 | D6: 정상 | E6: =IF(D6="정상",$C6,0) -> 0 | F6: 정상 | G6: =IF(F6="정상",$C6,0) -> 0 | H6: 정상 | I6: =IF(H6="정상",$C6,0) -> 0 | J6: 정상 | K6: =IF(J6="정상",$C6,0) -> 0 | L6: 정상 | M6: =IF(L6="정상",$C6,0) -> 0
A7: =IF(3<=DAY(DATE(YEAR(설정_코스수당!$K$2),MONTH(설정_코스수당!$K$2)+1,0)),DATE(YEAR(설정_코스수당!$K$2),MONTH(설정_코스수당!$K$2),3),"") -> 46176 | B7: =COUNTIFS(실시간콜입력!$B:$B,A7,실시간콜입력!$O:$O,"방문완료") -> 0 | C7: =IF(B7>=설정_코스수당!$A$71,설정_코스수당!$B$71,IF(B7>=설정_코스수당!$A$70,설정_코스수당!$B$70,IF(B7>=설정_코스수당!$A$69,설정_코스수당!$B$69,0))) -> 0 | D7: 정상 | E7: =IF(D7="정상",$C7,0) -> 0 | F7: 정상 | G7: =IF(F7="정상",$C7,0) -> 0 | H7: 정상 | I7: =IF(H7="정상",$C7,0) -> 0 | J7: 정상 | K7: =IF(J7="정상",$C7,0) -> 0 | L7: 정상 | M7: =IF(L7="정상",$C7,0) -> 0
A8: =IF(4<=DAY(DATE(YEAR(설정_코스수당!$K$2),MONTH(설정_코스수당!$K$2)+1,0)),DATE(YEAR(설정_코스수당!$K$2),MONTH(설정_코스수당!$K$2),4),"") -> 46177 | B8: =COUNTIFS(실시간콜입력!$B:$B,A8,실시간콜입력!$O:$O,"방문완료") -> 0 | C8: =IF(B8>=설정_코스수당!$A$71,설정_코스수당!$B$71,IF(B8>=설정_코스수당!$A$70,설정_코스수당!$B$70,IF(B8>=설정_코스수당!$A$69,설정_코스수당!$B$69,0))) -> 0 | D8: 정상 | E8: =IF(D8="정상",$C8,0) -> 0 | F8: 정상 | G8: =IF(F8="정상",$C8,0) -> 0 | H8: 정상 | I8: =IF(H8="정상",$C8,0) -> 0 | J8: 정상 | K8: =IF(J8="정상",$C8,0) -> 0 | L8: 정상 | M8: =IF(L8="정상",$C8,0) -> 0
A9: =IF(5<=DAY(DATE(YEAR(설정_코스수당!$K$2),MONTH(설정_코스수당!$K$2)+1,0)),DATE(YEAR(설정_코스수당!$K$2),MONTH(설정_코스수당!$K$2),5),"") -> 46178 | B9: =COUNTIFS(실시간콜입력!$B:$B,A9,실시간콜입력!$O:$O,"방문완료") -> 0 | C9: =IF(B9>=설정_코스수당!$A$71,설정_코스수당!$B$71,IF(B9>=설정_코스수당!$A$70,설정_코스수당!$B$70,IF(B9>=설정_코스수당!$A$69,설정_코스수당!$B$69,0))) -> 0 | D9: 정상 | E9: =IF(D9="정상",$C9,0) -> 0 | F9: 정상 | G9: =IF(F9="정상",$C9,0) -> 0 | H9: 정상 | I9: =IF(H9="정상",$C9,0) -> 0 | J9: 정상 | K9: =IF(J9="정상",$C9,0) -> 0 | L9: 정상 | M9: =IF(L9="정상",$C9,0) -> 0
A10: =IF(6<=DAY(DATE(YEAR(설정_코스수당!$K$2),MONTH(설정_코스수당!$K$2)+1,0)),DATE(YEAR(설정_코스수당!$K$2),MONTH(설정_코스수당!$K$2),6),"") -> 46179 | B10: =COUNTIFS(실시간콜입력!$B:$B,A10,실시간콜입력!$O:$O,"방문완료") -> 0 | C10: =IF(B10>=설정_코스수당!$A$71,설정_코스수당!$B$71,IF(B10>=설정_코스수당!$A$70,설정_코스수당!$B$70,IF(B10>=설정_코스수당!$A$69,설정_코스수당!$B$69,0))) -> 0 | D10: 정상 | E10: =IF(D10="정상",$C10,0) -> 0 | F10: 정상 | G10: =IF(F10="정상",$C10,0) -> 0 | H10: 정상 | I10: =IF(H10="정상",$C10,0) -> 0 | J10: 정상 | K10: =IF(J10="정상",$C10,0) -> 0 | L10: 정상 | M10: =IF(L10="정상",$C10,0) -> 0
A11: =IF(7<=DAY(DATE(YEAR(설정_코스수당!$K$2),MONTH(설정_코스수당!$K$2)+1,0)),DATE(YEAR(설정_코스수당!$K$2),MONTH(설정_코스수당!$K$2),7),"") -> 46180 | B11: =COUNTIFS(실시간콜입력!$B:$B,A11,실시간콜입력!$O:$O,"방문완료") -> 0 | C11: =IF(B11>=설정_코스수당!$A$71,설정_코스수당!$B$71,IF(B11>=설정_코스수당!$A$70,설정_코스수당!$B$70,IF(B11>=설정_코스수당!$A$69,설정_코스수당!$B$69,0))) -> 0 | D11: 정상 | E11: =IF(D11="정상",$C11,0) -> 0 | F11: 정상 | G11: =IF(F11="정상",$C11,0) -> 0 | H11: 정상 | I11: =IF(H11="정상",$C11,0) -> 0 | J11: 정상 | K11: =IF(J11="정상",$C11,0) -> 0 | L11: 정상 | M11: =IF(L11="정상",$C11,0) -> 0
